Workbook

Sheet Summary
A1: DATABASE ASET VIBRASI — PLTU JERANJANG
A4: KPI | B4: Nilai | D4: Status | E4: Jumlah | G4: Unit / Area | H4: Jumlah Aset
A5: Total report record | B5: =COUNTA(Report_Records!A2:A500) -> 69 | D5: NORMAL | E5: =COUNTIF(Report_Records!I2:I500,"NORMAL") -> 28 | G5: UNIT 1 | H5: =COUNTIF(Asset_Master!AT2:AT69,"UNIT 1") -> 18
A6: Aset logis unik | B6: =COUNTA(Asset_Master!A2:A500) -> 68 | D6: PREWARNING | E6: =COUNTIF(Report_Records!I2:I500,"PREWARNING") -> 39 | G6: UNIT 2 | H6: =COUNTIF(Asset_Master!AT2:AT69,"UNIT 2") -> 16
A7: KKS kosong (record) | B7: =COUNTBLANK(Report_Records!D2:D70) -> 9 | D7: WARNING | E7: =COUNTIF(Report_Records!I2:I500,"WARNING") -> 1 | G7: UNIT 3 | H7: =COUNTIF(Asset_Master!AT2:AT69,"UNIT 3") -> 20
A8: Status NORMAL | B8: =COUNTIF(Report_Records!I2:I500,"NORMAL") -> 28 | D8: ALARM | E8: =COUNTIF(Report_Records!I2:I500,"ALARM") -> 1 | G8: COMMON | H8: =COUNTIF(Asset_Master!AT2:AT69,"COMMON") -> 14
A9: Status non-NORMAL | B9: =COUNTIF(Report_Records!I2:I500,"PREWARNING")+COUNTIF(Report_Records!I2:I500,"WARNING")+COUNTIF(Report_Records!I2:I500,"ALARM") -> 41 | D9: TOTAL | E9: =SUM(E5:E8) -> 69 | G9: TOTAL | H9: =SUM(H5:H8) -> 68
A12: Catatan Ekstraksi
A13: Sumber | B13: VIbrasi dataset.pdf — 139 halaman
A14: Cakupan | B14: 69 detail report record; 68 identitas aset logis
A15: Prinsip | B15: Nilai sumber dipertahankan. Typo/spelling class tidak diubah; versi normalized disimpan pada kolom terpisah.
A16: Kualitas | B16: Nilai kosong pada PDF tetap kosong. Metadata aset berulang tetap dipertahankan di Report_Records.

Sheet Asset_Master
A1: Asset ID | B1: Equipment | C1: KKS | D1: Equipment Class (Source) | E1: Equipment Class (Normalized) | F1: Asset Category (Derived) | G1: PM Week | H1: Measurement Date | I1: Status Vibrasi | J1: Component 1 | K1: Component 2 | L1: C1 Type/Mfg | M1: C1 Speed | N1: C1 Power | O1: C1 Bearing Type | P1: C1 Inboard Bearing | Q1: C1 Outboard Bearing | R1: C1 Rotor Bar | S1: C1 Foundation | T1: C1 House Power | U1: C1 Brake Horse Power | V1: C1 Current | W1: C1 Rated Capacity | X1: C1 Rated Active Power | Y1: C1 Rated Stator Voltage | Z1: C1 Rated Stator Current | AA1: C1 Rated Speed | AB1: C1 Rated Frequency | AC1: C2 Type/Mfg | AD1: C2 Manufacturer | AE1: C2 Speed | AF1: C2 Power | AG1: C2 Capacity | AH1: C2 Pressure | AI1: C2 Flow Rate | AJ1: C2 Bearing Type | AK1: C2 Inboard Bearing | AL1: C2 Onboard Bearing | AM1: C2 Total Blade | AN1: C2 NCR | AO1: C2 Ekstraction | AP1: C2 Stages | AQ1: C2 Governoor Type | AR1: Source Pages | AS1: Data Quality Note | AT1: Unit Group (Derived)
A2: AST-001 | B2: Motor ID Fan 1#1 | C2: LJ10HNC10AN001-001 | D2: ISO 10816-3 (GROUP 1 RIGID) | E2: ISO 10816-3 (GROUP 1 RIGID) | F2: Fan | G2: W37 | H2: 45544 | I2: NORMAL | J2: MOTOR | K2: FAN | L2: YKK4003-4 | M2: 985 | N2: 355 Kw | P2: NU324 | Q2: 6324 | R2: - | S2: Rigid | AK2: - | AL2: - | AR2: 1 | AT2: =IF(VALUE(LEFT(AR2,FIND(",",AR2&",")-1))<=36,"UNIT 1",IF(VALUE(LEFT(AR2,FIND(",",AR2&",")-1))<=70,"UNIT 2",IF(VALUE(LEFT(AR2,FIND(",",AR2&",")-1))<=110,"UNIT 3","COMMON"))) -> UNIT 1
A3: AST-002 | B3: Motor ID Fan 2#1 | C3: LJ10HNC10AN002-001 | D3: ISO 10816-3 (GROUP 1 RIGID) | E3: ISO 10816-3 (GROUP 1 RIGID) | F3: Fan | G3: W39 | H3: 45558 | I3: PREWARNING | J3: MOTOR | K3: FAN | L3: YKK4003-4 | M3: 985 | N3: 355 Kw | P3: NU324 | Q3: 6324 | R3: - | S3: Rigid | AK3: - | AL3: - | AR3: 3 | AT3: =IF(VALUE(LEFT(AR3,FIND(",",AR3&",")-1))<=36,"UNIT 1",IF(VALUE(LEFT(AR3,FIND(",",AR3&",")-1))<=70,"UNIT 2",IF(VALUE(LEFT(AR3,FIND(",",AR3&",")-1))<=110,"UNIT 3","COMMON"))) -> UNIT 1
A4: AST-003 | B4: Motor Primary Air Fan 1#1 | C4: LJ10HLB10AN001-001 | D4: ISO 10816-3 (GROUP 1 RIGID) | E4: ISO 10816-3 (GROUP 1 RIGID) | F4: Fan | G4: W37 | H4: 45544 | I4: NORMAL | J4: MOTOR | K4: FAN | L4: YKK 4001-4 | M4: 1480 r/min | N4: 280 kW | O4: Roller Bearing | P4: NU324 | Q4: 6224 | R4: - | S4: Rigid | AC4: QALG-217D | AE4: 1450 r/min | AH4: 13500 Pa | AI4: 50000 m2/h | AJ4: - | AK4: - | AL4: - | AM4: - | AR4: 5 | AT4: =IF(VALUE(LEFT(AR4,FIND(",",AR4&",")-1))<=36,"UNIT 1",IF(VALUE(LEFT(AR4,FIND(",",AR4&",")-1))<=70,"UNIT 2",IF(VALUE(LEFT(AR4,FIND(",",AR4&",")-1))<=110,"UNIT 3","COMMON"))) -> UNIT 1
A5: AST-004 | B5: Motor Primary Air Fan 2#1 | C5: LJ10HLB10AN002-001 | D5: ISO 10816-3 (GROUP 1 RIGID) | E5: ISO 10816-3 (GROUP 1 RIGID) | F5: Fan | G5: W39 | H5: 45558 | I5: NORMAL | J5: MOTOR | K5: FAN | L5: YKK 4001-4 | M5: 1480 r/min | N5: 280 kW | O5: Roller Bearing | P5: NU324 | Q5: 6224 | R5: - | S5: Rigid | AC5: QALG-217D | AE5: 1450 r/min | AH5: 13500 Pa | AI5: 50000 m2/h | AJ5: - | AK5: - | AL5: - | AM5: - | AR5: 7 | AT5: =IF(VALUE(LEFT(AR5,FIND(",",AR5&",")-1))<=36,"UNIT 1",IF(VALUE(LEFT(AR5,FIND(",",AR5&",")-1))<=70,"UNIT 2",IF(VALUE(LEFT(AR5,FIND(",",AR5&",")-1))<=110,"UNIT 3","COMMON"))) -> UNIT 1
A6: AST-005 | B6: Motor Secondary Air Fan 1#1 | C6: LJ10HLB10AN003-001 | D6: ISO 10816-3 (GROUP 1 RIGID) | E6: ISO 10816-3 (GROUP 1 RIGID) | F6: Fan | G6: W37 | H6: 45544 | I6: NORMAL | J6: MOTOR | K6: FAN | L6: YKK 4001-4 | M6: 1480 r/min | N6: 280 kW | O6: Roller Bearing | P6: NU324 | Q6: 6224 | R6: - | S6: Rigid | AC6: QALG-217D | AE6: 1450 r/min | AH6: 13500 Pa | AI6: 50000 m2/h | AJ6: - | AK6: - | AL6: - | AM6: - | AR6: 9 | AT6: =IF(VALUE(LEFT(AR6,FIND(",",AR6&",")-1))<=36,"UNIT 1",IF(VALUE(LEFT(AR6,FIND(",",AR6&",")-1))<=70,"UNIT 2",IF(VALUE(LEFT(AR6,FIND(",",AR6&",")-1))<=110,"UNIT 3","COMMON"))) -> UNIT 1
A7: AST-006 | B7: Motor Secondary Air Fan 2#1 | C7: LJ10HLB10AN004-001 | D7: ISO 10816-3 (GROUP 1 RIGID) | E7: ISO 10816-3 (GROUP 1 RIGID) | F7: Fan | G7: W39 | H7: 45558 | I7: PREWARNING | J7: MOTOR | K7: FAN | L7: YKK 4001-4 | M7: 1480 r/min | N7: 280 kW | O7: Roller Bearing | P7: NU324 | Q7: 6224 | R7: - | S7: Rigid | AC7: QALG-217D | AE7: 1450 r/min | AH7: 13500 Pa | AI7: 50000 m2/h | AJ7: - | AK7: - | AL7: - | AM7: - | AR7: 11 | AT7: =IF(VALUE(LEFT(AR7,FIND(",",AR7&",")-1))<=36,"UNIT 1",IF(VALUE(LEFT(AR7,FIND(",",AR7&",")-1))<=70,"UNIT 2",IF(VALUE(LEFT(AR7,FIND(",",AR7&",")-1))<=110,"UNIT 3","COMMON"))) -> UNIT 1
A8: AST-007 | B8: Turbin-Generator#1 | C8: LJ10MAA10HB010-001 | D8: ISO 10816-2 | E8: ISO 10816-2 | F8: Turbine-Generator | G8: W37 | H8: 45544 | I8: NORMAL | J8: GENERATOR | K8: TURBINE | L8: China Changjiang Energy Corp. | W8: 37.5 MVA | X8: 30 MW | Y8: 6.3 kV Phase 3 Wire | AA8: 3000 r/min | AB8: 50 Hz | AD8: China Changjiang Energy Corp. | AE8: 3000 r/min | AN8: 30 MW | AO8: 6 | AP8: 19 | AQ8: Digital Electric Hidroulic (Woodard 505) | AR8: 13 | AT8: =IF(VALUE(LEFT(AR8,FIND(",",AR8&",")-1))<=36,"UNIT 1",IF(VALUE(LEFT(AR8,FIND(",",AR8&",")-1))<=70,"UNIT 2",IF(VALUE(LEFT(AR8,FIND(",",AR8&",")-1))<=110,"UNIT 3","COMMON"))) -> UNIT 1
A9: AST-008 | B9: Motor Condensat Pump 2#1 | C9: LJ10LCB10AP020-001 | D9: ISO 10816-3 (GROUP 2 RIGID) | E9: ISO 10816-3 (GROUP 2 RIGID) | F9: Pump | G9: W36 | H9: 45537 | I9: PREWARNING | J9: MOTOR | K9: POMPA | L9: YLB 250-2-4 | M9: 1430 rpm | N9: 75 kW | O9: - | P9: - | Q9: - | R9: - | S9: Rigid | AC9: 5LDIN | AE9: 1480 rpm | AF9: 53 kW | AG9: 120 m3/h | AK9: - | AL9: - | AR9: 15 | AT9: =IF(VALUE(LEFT(AR9,FIND(",",AR9&",")-1))<=36,"UNIT 1",IF(VALUE(LEFT(AR9,FIND(",",AR9&",")-1))<=70,"UNIT 2",IF(VALUE(LEFT(AR9,FIND(",",AR9&",")-1))<=110,"UNIT 3","COMMON"))) -> UNIT 1
A10: AST-009 | B10: Motor Vacuum Pump 1#1 | C10: LJ10MAG10AP011-001 | D10: ISO 10816-3 (GROUP 2 RIGID) | E10: ISO 10816-3 (GROUP 2 RIGID) | F10: Pump | G10: W39 | H10: 45558 | I10: NORMAL | J10: MOTOR | K10: POMPA | L10: Y2 - 250-6 | M10: 980 rpm | N10: 37 kW | R10: - | S10: Rigid | AK10: - | AL10: - | AR10: 17 | AT10: =IF(VALUE(LEFT(AR10,FIND(",",AR10&",")-1))<=36,"UNIT 1",IF(VALUE(LEFT(AR10,FIND(",",AR10&",")-1))<=70,"UNIT 2",IF(VALUE(LEFT(AR10,FIND(",",AR10&",")-1))<=110,"UNIT 3","COMMON"))) -> UNIT 1
A11: AST-010 | B11: Motor Vacuum Pump 2#1 | C11: LJ10MAG10AP012-001 | D11: ISO 10816-3 (GROUP 2 RIGID) | E11: ISO 10816-3 (GROUP 2 RIGID) | F11: Pump | G11: W39 | H11: 45558 | I11: NORMAL | J11: MOTOR | K11: POMPA | L11: Y2 - 250-6 | M11: 980 rpm | N11: 37 kW | R11: - | S11: Rigid | AK11: - | AL11: - | AR11: 19 | AT11: =IF(VALUE(LEFT(AR11,FIND(",",AR11&",")-1))<=36,"UNIT 1",IF(VALUE(LEFT(AR11,FIND(",",AR11&",")-1))<=70,"UNIT 2",IF(VALUE(LEFT(AR11,FIND(",",AR11&",")-1))<=110,"UNIT 3","COMMON"))) -> UNIT 1
A12: AST-011 | B12: Motor Boiler Feed Pump 1#1 | C12: LJ10LAC10AP001-001 | D12: ISO 10816-3 (GROUP 1 RIGID) | E12: ISO 10816-3 (GROUP 1 RIGID) | F12: Pump | G12: W36 | H12: 45537 | I12: NORMAL | J12: MOTOR | K12: POMPA | L12: SY23372-1028, QINGJIANG | M12: 2980 rpm | N12: 1000 | P12: NU 224EC | Q12: 6224/C3 | R12: - | S12: Rigid | AC12: SHENYANG AST PUMP MANUFACTURING CO.,LTD | AE12: 2980 rpm | AG12: 140 | AK12: - | AL12: - | AR12: 21 | AT12: =IF(VALUE(LEFT(AR12,FIND(",",AR12&",")-1))<=36,"UNIT 1",IF(VALUE(LEFT(AR12,FIND(",",AR12&",")-1))<=70,"UNIT 2",IF(VALUE(LEFT(AR12,FIND(",",AR12&",")-1))<=110,"UNIT 3","COMMON"))) -> UNIT 1
A13: AST-012 | B13: Motor CCCWP 1#1 | C13: LJ10PGB10AP001-001 | D13: ISO 10816-3 (GROUP 2 RIGID) | E13: ISO 10816-3 (GROUP 2 RIGID) | F13: Pump | G13: W37 | H13: 45545 | I13: PREWARNING | J13: MOTOR | K13: POMPA | L13: Y2 - 280-4 | M13: 980 rpm | N13: 75 kW | O13: - | P13: - | Q13: - | R13: - | S13: Rigid | AK13: - | AL13: - | AR13: 23 | AT13: =IF(VALUE(LEFT(AR13,FIND(",",AR13&",")-1))<=36,"UNIT 1",IF(VALUE(LEFT(AR13,FIND(",",AR13&",")-1))<=70,"UNIT 2",IF(VALUE(LEFT(AR13,FIND(",",AR13&",")-1))<=110,"UNIT 3","COMMON"))) -> UNIT 1
A14: AST-013 | B14: Motor CCCWP 2#1 | C14: LJ10PGB10AP002-001 | D14: ISO 10816-3 (GROUP 2 RIGID) | E14: ISO 10816-3 (GROUP 2 RIGID) | F14: Pump | G14: W39 | H14: 45559 | I14: NORMAL | J14: MOTOR | K14: POMPA | L14: Y2 - 280-4 | M14: 980 rpm | N14: 75 kW | R14: - | S14: Rigid | AK14: - | AL14: - | AR14: 25 | AT14: =IF(VALUE(LEFT(AR14,FIND(",",AR14&",")-1))<=36,"UNIT 1",IF(VALUE(LEFT(AR14,FIND(",",AR14&",")-1))<=70,"UNIT 2",IF(VALUE(LEFT(AR14,FIND(",",AR14&",")-1))<=110,"UNIT 3","COMMON"))) -> UNIT 1
A15: AST-014 | B15: Motor CWP 355 Kw 1#1 | C15: LJ10PAC10AP001-001 | D15: ISO 10816-3 (GROUP 1 RIGID)) | E15: ISO 10816-3 (GROUP 1 RIGID) | F15: Pump | G15: W39 | H15: 45559 | I15: PREWARNING | J15: MOTOR | K15: POMPA | L15: YLKK400-6 | M15: 991 | N15: 315 | R15: - | S15: Rigid | AR15: 27 | AS15: Class dinormalisasi pada kolom terpisah; nilai sumber dipertahankan | AT15: =IF(VALUE(LEFT(AR15,FIND(",",AR15&",")-1))<=36,"UNIT 1",IF(VALUE(LEFT(AR15,FIND(",",AR15&",")-1))<=70,"UNIT 2",IF(VALUE(LEFT(AR15,FIND(",",AR15&",")-1))<=110,"UNIT 3","COMMON"))) -> UNIT 1
A16: AST-015 | B16: Motor CWP 355 Kw 2#1 | C16: LJ10PAC10AP002-001 | D16: ISO 10816-3 (GROUP 1 RIGID)) | E16: ISO 10816-3 (GROUP 1 RIGID) | F16: Pump | G16: W37 | H16: 45545 | I16: NORMAL | J16: MOTOR | K16: POMPA | L16: YLKK400-6 | M16: 991 | N16: 315 | R16: - | S16: Rigid | AR16: 29 | AS16: Class dinormalisasi pada kolom terpisah; nilai sumber dipertahankan | AT16: =IF(VALUE(LEFT(AR16,FIND(",",AR16&",")-1))<=36,"UNIT 1",IF(VALUE(LEFT(AR16,FIND(",",AR16&",")-1))<=70,"UNIT 2",IF(VALUE(LEFT(AR16,FIND(",",AR16&",")-1))<=110,"UNIT 3","COMMON"))) -> UNIT 1
A17: AST-016 | B17: Motor BWRO 1#1 | C17: LJ10GCK10AP005-001 | D17: ISO 10816-3 (GROUP 2 RIGID) | E17: ISO 10816-3 (GROUP 2 RIGID) | F17: Pump | G17: W37 | H17: 45545 | I17: PREWARNING | J17: MOTOR | K17: POMPA | L17: AEUBKG020015FMBP3 | M17: 2920 r/min | N17: 11 kw | O17: Roller Bearing | P17: 7309B | Q17: 6307C3 | R17: - | S17: Rigid | AC17: A96536974P11003 | AE17: 2920 r/min | AF17: 11 Kw | AG17: 21 m3/h | AK17: - | AL17: - | AR17: 32 | AT17: =IF(VALUE(LEFT(AR17,FIND(",",AR17&",")-1))<=36,"UNIT 1",IF(VALUE(LEFT(AR17,FIND(",",AR17&",")-1))<=70,"UNIT 2",IF(VALUE(LEFT(AR17,FIND(",",AR17&",")-1))<=110,"UNIT 3","COMMON"))) -> UNIT 1
A18: AST-017 | B18: Motor SWRO 2#1 | C18: LJ10GCK10AP008-001 | D18: ISO 10816-3 (GROUP 2 RIGID) | E18: ISO 10816-3 (GROUP 2 RIGID) | F18: Pump | G18: W39 | H18: 45559 | I18: NORMAL | J18: MOTOR | K18: POMPA | M18: 2970 r/min | N18: 75 | R18: - | S18: Rigid | AK18: - | AL18: - | AR18: 34 | AT18: =IF(VALUE(LEFT(AR18,FIND(",",AR18&",")-1))<=36,"UNIT 1",IF(VALUE(LEFT(AR18,FIND(",",AR18&",")-1))<=70,"UNIT 2",IF(VALUE(LEFT(AR18,FIND(",",AR18&",")-1))<=110,"UNIT 3","COMMON"))) -> UNIT 1
A19: AST-018 | B19: AC OIL PUMP UNIT 1 | D19: ISO 10816-3 (GROUP 2 RIGID) | E19: ISO 10816-3 (GROUP 2 RIGID) | F19: Pump | G19: W38 | H19: 45551 | I19: PREWARNING | J19: MOTOR | K19: POMPA | L19: Y2 - 250-6 | M19: 980 rpm | N19: 37 kW | R19: - | S19: Rigid | AK19: - | AL19: - | AR19: 36 | AS19: KKS kosong pada sumber PDF | AT19: =IF(VALUE(LEFT(AR19,FIND(",",AR19&",")-1))<=36,"UNIT 1",IF(VALUE(LEFT(AR19,FIND(",",AR19&",")-1))<=70,"UNIT 2",IF(VALUE(LEFT(AR19,FIND(",",AR19&",")-1))<=110,"UNIT 3","COMMON"))) -> UNIT 1
A20: AST-019 | B20: Motor ID Fan 1#2 | C20: LJ20HNC10AN001-001 | D20: ISO 10816-3 (GROUP 1 RIGID) | E20: ISO 10816-3 (GROUP 1 RIGID) | F20: Fan | G20: W39 | H20: 45559 | I20: NORMAL | J20: MOTOR | K20: FAN | L20: YKK4003-4 | M20: 985 | N20: 355 Kw | P20: NU324 | Q20: 6324 | R20: - | S20: Rigid | AK20: - | AL20: - | AR20: 38 | AT20: =IF(VALUE(LEFT(AR20,FIND(",",AR20&",")-1))<=36,"UNIT 1",IF(VALUE(LEFT(AR20,FIND(",",AR20&",")-1))<=70,"UNIT 2",IF(VALUE(LEFT(AR20,FIND(",",AR20&",")-1))<=110,"UNIT 3","COMMON"))) -> UNIT 2
A21: AST-020 | B21: Motor ID Fan 2#2 | C21: LJ20HNC10AN002-001 | D21: ISO 10816-3 (GROUP 1 RIGID) | E21: ISO 10816-3 (GROUP 1 RIGID) | F21: Fan | G21: W37 | H21: 45545 | I21: PREWARNING | J21: MOTOR | K21: FAN | L21: YKK4003-4 | M21: 985 | N21: 355 Kw | P21: NU324 | Q21: 6324 | R21: - | S21: Rigid | AK21: - | AL21: - | AR21: 40 | AT21: =IF(VALUE(LEFT(AR21,FIND(",",AR21&",")-1))<=36,"UNIT 1",IF(VALUE(LEFT(AR21,FIND(",",AR21&",")-1))<=70,"UNIT 2",IF(VALUE(LEFT(AR21,FIND(",",AR21&",")-1))<=110,"UNIT 3","COMMON"))) -> UNIT 2
A22: AST-021 | B22: Motor Primary Air Fan 1#2 | C22: LJ20HLB10AN001-001 | D22: ISO 10816-3 (GROUP 1 RIGID) | E22: ISO 10816-3 (GROUP 1 RIGID) | F22: Fan | G22: W39 | H22: 45560 | I22: NORMAL | J22: MOTOR | K22: FAN | L22: YKK 4001-4 | M22: 1480 r/min | N22: 280 kW | O22: Roller Bearing | P22: NU324 | Q22: 6224 | R22: - | S22: Rigid | AC22: QALG-217D | AE22: 1450 r/min | AH22: 13500 Pa | AI22: 50000 m2/h | AJ22: - | AK22: - | AL22: - | AM22: - | AR22: 42 | AT22: =IF(VALUE(LEFT(AR22,FIND(",",AR22&",")-1))<=36,"UNIT 1",IF(VALUE(LEFT(AR22,FIND(",",AR22&",")-1))<=70,"UNIT 2",IF(VALUE(LEFT(AR22,FIND(",",AR22&",")-1))<=110,"UNIT 3","COMMON"))) -> UNIT 2
A23: AST-022 | B23: Motor Primary Air Fan 2#2 | C23: LJ20HLB10AN002-001 | D23: ISO 10816-3 (GROUP 1 RIGID) | E23: ISO 10816-3 (GROUP 1 RIGID) | F23: Fan | G23: W37 | H23: 45546 | I23: NORMAL | J23: MOTOR | K23: FAN | L23: YKK 4001-4 | M23: 1480 r/min | N23: 280 kW | O23: Roller Bearing | P23: NU324 | Q23: 6224 | R23: - | S23: Rigid | AC23: QALG-217D | AE23: 1450 r/min | AH23: 13500 Pa | AI23: 50000 m2/h | AJ23: - | AK23: - | AL23: - | AM23: - | AR23: 44 | AT23: =IF(VALUE(LEFT(AR23,FIND(",",AR23&",")-1))<=36,"UNIT 1",IF(VALUE(LEFT(AR23,FIND(",",AR23&",")-1))<=70,"UNIT 2",IF(VALUE(LEFT(AR23,FIND(",",AR23&",")-1))<=110,"UNIT 3","COMMON"))) -> UNIT 2
A24: AST-023 | B24: Motor Secondary Air Fan 1#2 | C24: LJ20HLB10AN003-001 | D24: ISO 10816-3 (GROUP 1 RIGID) | E24: ISO 10816-3 (GROUP 1 RIGID) | F24: Fan | G24: W39 | H24: 45560 | I24: PREWARNING | J24: MOTOR | K24: FAN | L24: YKK 4001-4 | M24: 1480 r/min | N24: 280 kW | O24: Roller Bearing | P24: NU324 | Q24: 6224 | R24: - | S24: Rigid | AC24: QALG-217D | AE24: 1450 r/min | AH24: 13500 Pa | AI24: 50000 m2/h | AJ24: - | AK24: - | AL24: - | AM24: - | AR24: 46 | AT24: =IF(VALUE(LEFT(AR24,FIND(",",AR24&",")-1))<=36,"UNIT 1",IF(VALUE(LEFT(AR24,FIND(",",AR24&",")-1))<=70,"UNIT 2",IF(VALUE(LEFT(AR24,FIND(",",AR24&",")-1))<=110,"UNIT 3","COMMON"))) -> UNIT 2
A25: AST-024 | B25: Motor Secondary Air Fan 2#2 | C25: LJ20HLB10AN004-001 | D25: ISO 10816-3 (GROUP 1 RIGID) | E25: ISO 10816-3 (GROUP 1 RIGID) | F25: Fan | G25: W37 | H25: 45546 | I25: NORMAL | J25: MOTOR | K25: FAN | L25: YKK 4001-4 | M25: 1480 r/min | N25: 280 kW | O25: Roller Bearing | P25: NU324 | Q25: 6224 | R25: - | S25: Rigid | AC25: QALG-217D | AE25: 1450 r/min | AH25: 13500 Pa | AI25: 50000 m2/h | AJ25: - | AK25: - | AL25: - | AM25: - | AR25: 48 | AT25: =IF(VALUE(LEFT(AR25,FIND(",",AR25&",")-1))<=36,"UNIT 1",IF(VALUE(LEFT(AR25,FIND(",",AR25&",")-1))<=70,"UNIT 2",IF(VALUE(LEFT(AR25,FIND(",",AR25&",")-1))<=110,"UNIT 3","COMMON"))) -> UNIT 2
A26: AST-025 | B26: Turbin-Generator#2 | C26: LJ20MAA10HB010-001 | D26: ISO 10816-2 | E26: ISO 10816-2 | F26: Turbine-Generator | G26: W39 | H26: 45560 | I26: PREWARNING | J26: GENERATOR | K26: TURBINE | L26: China Changjiang Energy Corp. | W26: 37.5 MVA | X26: 30 MW | Y26: 6.3 kV Phase 3 Wire | AA26: 3000 r/min | AB26: 50 Hz | AD26: China Changjiang Energy Corp. | AE26: 3000 r/min | AN26: 30 MW | AO26: 6 | AP26: 19 | AQ26: Digital Electric Hidroulic (Woodard 505) | AR26: 50 | AT26: =IF(VALUE(LEFT(AR26,FIND(",",AR26&",")-1))<=36,"UNIT 1",IF(VALUE(LEFT(AR26,FIND(",",AR26&",")-1))<=70,"UNIT 2",IF(VALUE(LEFT(AR26,FIND(",",AR26&",")-1))<=110,"UNIT 3","COMMON"))) -> UNIT 2
A27: AST-026 | B27: Motor Condensat Pump 1#2 | C27: LJ20LCB10AP010-001 | D27: ISO 10816-3 (GROUP 2 RIGID) | E27: ISO 10816-3 (GROUP 2 RIGID) | F27: Pump | G27: W36 | H27: 45537 | I27: NORMAL | J27: MOTOR | K27: POMPA | L27: YLB 250-2-4 | M27: 1430 rpm | N27: 75 kW | O27: - | P27: - | Q27: - | R27: - | S27: Rigid | AK27: - | AL27: - | AR27: 52 | AT27: =IF(VALUE(LEFT(AR27,FIND(",",AR27&",")-1))<=36,"UNIT 1",IF(VALUE(LEFT(AR27,FIND(",",AR27&",")-1))<=70,"UNIT 2",IF(VALUE(LEFT(AR27,FIND(",",AR27&",")-1))<=110,"UNIT 3","COMMON"))) -> UNIT 2
A28: AST-027 | B28: Motor Vacuum Pump 1#2 | C28: LJ20MAG10AP011-001 | D28: ISO 10816-3 (GROUP 2 RIGID) | E28: ISO 10816-3 (GROUP 2 RIGID) | F28: Pump | G28: W39 | H28: 45561 | I28: PREWARNING | J28: MOTOR | K28: POMPA | L28: Y2 - 250-6 | M28: 980 rpm | N28: 37 kW | R28: - | S28: Rigid | AK28: - | AL28: - | AR28: 54 | AT28: =IF(VALUE(LEFT(AR28,FIND(",",AR28&",")-1))<=36,"UNIT 1",IF(VALUE(LEFT(AR28,FIND(",",AR28&",")-1))<=70,"UNIT 2",IF(VALUE(LEFT(AR28,FIND(",",AR28&",")-1))<=110,"UNIT 3","COMMON"))) -> UNIT 2
A29: AST-028 | B29: Motor Vacuum Pump 2#2 | C29: LJ20MAG10AP012-001 | D29: ISO 10816-3 (GROUP 2 RIGID) | E29: ISO 10816-3 (GROUP 2 RIGID) | F29: Pump | G29: W39 | H29: 45561 | I29: PREWARNING | J29: MOTOR | K29: POMPA | L29: Y2 - 250-6 | M29: 980 rpm | N29: 37 kW | R29: - | S29: Rigid | AK29: - | AL29: - | AR29: 56 | AT29: =IF(VALUE(LEFT(AR29,FIND(",",AR29&",")-1))<=36,"UNIT 1",IF(VALUE(LEFT(AR29,FIND(",",AR29&",")-1))<=70,"UNIT 2",IF(VALUE(LEFT(AR29,FIND(",",AR29&",")-1))<=110,"UNIT 3","COMMON"))) -> UNIT 2
A30: AST-029 | B30: Motor Boiler Feed Pump 2#2 | C30: LJ20LAC10AP002-001 | D30: ISO 10816-3 (GROUP 1 RIGID) | E30: ISO 10816-3 (GROUP 1 RIGID) | F30: Pump | G30: W36 | H30: 45537 | I30: PREWARNING | J30: MOTOR | K30: FAN | L30: SY23372-1028, QINGJIANG | M30: 2980 rpm | N30: 1000 | P30: NU 224EC | Q30: 6224/C3 | R30: - | S30: Rigid | AC30: SHENYANG AST PUMP MANUFACTURING CO.,LTD | AE30: 2980 rpm | AG30: 140 | AK30: - | AL30: - | AR30: 58 | AT30: =IF(VALUE(LEFT(AR30,FIND(",",AR30&",")-1))<=36,"UNIT 1",IF(VALUE(LEFT(AR30,FIND(",",AR30&",")-1))<=70,"UNIT 2",IF(VALUE(LEFT(AR30,FIND(",",AR30&",")-1))<=110,"UNIT 3","COMMON"))) -> UNIT 2
A31: AST-030 | B31: Motor CCCWP 1#2 | C31: LJ20PGB10AP001-001 | D31: ISO 10816-3 (GROUP 2 RIGID) | E31: ISO 10816-3 (GROUP 2 RIGID) | F31: Pump | G31: W39 | H31: 45561 | I31: PREWARNING | J31: MOTOR | K31: POMPA | L31: Y2 - 280-4 | M31: 980 rpm | N31: 75 kW | O31: - | P31: - | Q31: - | R31: - | S31: Rigid | AK31: - | AL31: - | AR31: 60 | AT31: =IF(VALUE(LEFT(AR31,FIND(",",AR31&",")-1))<=36,"UNIT 1",IF(VALUE(LEFT(AR31,FIND(",",AR31&",")-1))<=70,"UNIT 2",IF(VALUE(LEFT(AR31,FIND(",",AR31&",")-1))<=110,"UNIT 3","COMMON"))) -> UNIT 2
A32: AST-031 | B32: Motor CCCWP 2#2 | C32: LJ20PGB10AP002-001 | D32: ISO 10816-3 (GROUP 2 RIGID) | E32: ISO 10816-3 (GROUP 2 RIGID) | F32: Pump | G32: W39 | H32: 45561 | I32: PREWARNING | J32: MOTOR | K32: POMPA | L32: Y2 - 280-4 | M32: 980 rpm | N32: 75 kW | R32: - | S32: Rigid | AK32: - | AL32: - | AR32: 62 | AT32: =IF(VALUE(LEFT(AR32,FIND(",",AR32&",")-1))<=36,"UNIT 1",IF(VALUE(LEFT(AR32,FIND(",",AR32&",")-1))<=70,"UNIT 2",IF(VALUE(LEFT(AR32,FIND(",",AR32&",")-1))<=110,"UNIT 3","COMMON"))) -> UNIT 2
A33: AST-032 | B33: Motor CWP 355 Kw 1#2 | C33: LJ20PAC10AP001-001 | D33: ISO 10816-3 (GROUP 1 RIGID)) | E33: ISO 10816-3 (GROUP 1 RIGID) | F33: Pump | G33: W38 | H33: 45552 | I33: NORMAL | J33: MOTOR | K33: POMPA | L33: YLKK400-6 | M33: 991 | N33: 315 | R33: - | S33: Rigid | AR33: 64 | AS33: Class dinormalisasi pada kolom terpisah; nilai sumber dipertahankan | AT33: =IF(VALUE(LEFT(AR33,FIND(",",AR33&",")-1))<=36,"UNIT 1",IF(VALUE(LEFT(AR33,FIND(",",AR33&",")-1))<=70,"UNIT 2",IF(VALUE(LEFT(AR33,FIND(",",AR33&",")-1))<=110,"UNIT 3","COMMON"))) -> UNIT 2
A34: AST-033 | B34: Motor CWP 355 Kw 2#2 | C34: LJ20PAC10AP002-001 | D34: ISO 10816-3 (GROUP 1 RIGID)) | E34: ISO 10816-3 (GROUP 1 RIGID) | F34: Pump | G34: W36 | H34: 45537 | I34: NORMAL | J34: MOTOR | K34: POMPA | L34: YLKK400-6 | M34: 991 | N34: 315 | R34: - | S34: Rigid | AR34: 66 | AS34: Class dinormalisasi pada kolom terpisah; nilai sumber dipertahankan | AT34: =IF(VALUE(LEFT(AR34,FIND(",",AR34&",")-1))<=36,"UNIT 1",IF(VALUE(LEFT(AR34,FIND(",",AR34&",")-1))<=70,"UNIT 2",IF(VALUE(LEFT(AR34,FIND(",",AR34&",")-1))<=110,"UNIT 3","COMMON"))) -> UNIT 2
A35: AST-034 | B35: ACA OIL PUMP UNIT 2 | D35: ISO 10816-3 (GROUP 2 RIGID) | E35: ISO 10816-3 (GROUP 2 RIGID) | F35: Pump | G35: W38 | H35: 45552 | I35: PREWARNING | J35: MOTOR | K35: POMPA | L35: Y2 - 250-6 | M35: 980 rpm | N35: 37 kW | R35: - | S35: Rigid | AK35: - | AL35: - | AR35: 68, 70 | AS35: KKS kosong pada sumber PDF; Metadata aset yang sama muncul pada halaman 68, 70; Lebih dari satu report record dengan metadata aset yang sama | AT35: =IF(VALUE(LEFT(AR35,FIND(",",AR35&",")-1))<=36,"UNIT 1",IF(VALUE(LEFT(AR35,FIND(",",AR35&",")-1))<=70,"UNIT 2",IF(VALUE(LEFT(AR35,FIND(",",AR35&",")-1))<=110,"UNIT 3","COMMON"))) -> UNIT 2
A36: AST-035 | B36: Motor ID Fan 1#3 | C36: LJ03HNC10AN001-001 | D36: ISO 10816-3 (GROUP 1 RIGID) | E36: ISO 10816-3 (GROUP 1 RIGID) | F36: Fan | G36: W38 | H36: 45552 | I36: NORMAL | J36: MOTOR | K36: FAN | L36: YKK 4504-6 | M36: 990 | N36: 450 | O36: Roller Bearing | P36: NU228E/C3 | Q36: 6226/C3 | R36: - | S36: Rigid | AC36: 25 SB-P | AE36: 2980 r/min | AG36: 165 m3/h | AJ36: Journal Bearing | AK36: - | AL36: - | AR36: 72 | AT36: =IF(VALUE(LEFT(AR36,FIND(",",AR36&",")-1))<=36,"UNIT 1",IF(VALUE(LEFT(AR36,FIND(",",AR36&",")-1))<=70,"UNIT 2",IF(VALUE(LEFT(AR36,FIND(",",AR36&",")-1))<=110,"UNIT 3","COMMON"))) -> UNIT 3
A37: AST-036 | B37: Motor ID Fan 2#3 | C37: LJ03HNC20AN001-001 | D37: ISO 10816-3 (GROUP 1 RIGID) | E37: ISO 10816-3 (GROUP 1 RIGID) | F37: Fan | G37: W36 | H37: 45538 | I37: NORMAL | J37: MOTOR | K37: FAN | L37: YKK 4504-6 | M37: 990 | N37: 450 | O37: Roller Bearing | P37: NU228E/C3 | Q37: 6226/C3 | R37: - | S37: Rigid | AC37: 25 SB-P | AE37: 2980 r/min | AG37: 165 m3/h | AJ37: Journal Bearing | AK37: - | AL37: - | AR37: 74 | AT37: =IF(VALUE(LEFT(AR37,FIND(",",AR37&",")-1))<=36,"UNIT 1",IF(VALUE(LEFT(AR37,FIND(",",AR37&",")-1))<=70,"UNIT 2",IF(VALUE(LEFT(AR37,FIND(",",AR37&",")-1))<=110,"UNIT 3","COMMON"))) -> UNIT 3
A38: AST-037 | B38: Motor Primary Air Fan#3 | C38: LJ03HLB10AN001-001 | D38: ISO 10816-3 (GROUP 1 RIGID) | E38: ISO 10816-3 (GROUP 1 RIGID) | F38: Fan | G38: W36 | H38: 45538 | I38: PREWARNING | J38: MOTOR | K38: FAN | L38: YKK 4504-4 | M38: 1490 | N38: 630 | O38: Roller Bearing | P38: NU226E/C3 | Q38: 6228/C3 | R38: - | S38: Rigid | AC38: G6-30 19.50 | AE38: 1485 r/min | AF38: 630 Kw | AI38: 400871 m2/h | AJ38: Journal Bearing | AK38: - | AL38: - | AM38: - | AR38: 76 | AT38: =IF(VALUE(LEFT(AR38,FIND(",",AR38&",")-1))<=36,"UNIT 1",IF(VALUE(LEFT(AR38,FIND(",",AR38&",")-1))<=70,"UNIT 2",IF(VALUE(LEFT(AR38,FIND(",",AR38&",")-1))<=110,"UNIT 3","COMMON"))) -> UNIT 3
A39: AST-038 | B39: Motor Secondary Air Fan#3 | C39: LJ03HLB20AN001-001 | D39: ISO 10816-3 (GROUP 1 RIGID) | E39: ISO 10816-3 (GROUP 1 RIGID) | F39: Fan | G39: W39 | H39: 45561 | I39: PREWARNING | J39: MOTOR | K39: FAN | L39: YKK 4504-4 | M39: 1485 | N39: 400 | O39: Roller Bearing | P39: NU224EC | Q39: 6224/C3 | R39: - | S39: Rigid | AC39: G6-40 16.20 | AE39: 1485 r/min | AF39: 400 Kw | AI39: 87120 m2/h | AJ39: Journal Bearing | AK39: - | AL39: - | AM39: - | AR39: 78 | AT39: =IF(VALUE(LEFT(AR39,FIND(",",AR39&",")-1))<=36,"UNIT 1",IF(VALUE(LEFT(AR39,FIND(",",AR39&",")-1))<=70,"UNIT 2",IF(VALUE(LEFT(AR39,FIND(",",AR39&",")-1))<=110,"UNIT 3","COMMON"))) -> UNIT 3
A40: AST-039 | B40: Motor Recirculating Air Fan 2#3 | C40: LJ03PAD11AN001-001 | D40: ISO 10816-3 (GROUP 2 RIGID) | E40: ISO 10816-3 (GROUP 2 RIGID) | F40: Fan | G40: W36 | H40: 45538 | I40: PREWARNING | J40: MOTOR | K40: FAN | L40: Y2-250M-4-B3 | M40: 1480 | N40: 55 | O40: Ball Bearing | P40: 6314/CM | Q40: 6313/CM | R40: - | S40: Rigid | AR40: 80 | AT40: =IF(VALUE(LEFT(AR40,FIND(",",AR40&",")-1))<=36,"UNIT 1",IF(VALUE(LEFT(AR40,FIND(",",AR40&",")-1))<=70,"UNIT 2",IF(VALUE(LEFT(AR40,FIND(",",AR40&",")-1))<=110,"UNIT 3","COMMON"))) -> UNIT 3
...

Sheet Report_Records
A1: Record ID | B1: Asset ID | C1: Equipment | D1: KKS | E1: Equipment Class (Source) | F1: Equipment Class (Normalized) | G1: PM Week | H1: Measurement Date | I1: Status Vibrasi | J1: Component 1 | K1: Component 2 | L1: C1 Type/Mfg | M1: C1 Speed | N1: C1 Power | O1: C1 Bearing Type | P1: C1 Inboard Bearing | Q1: C1 Outboard Bearing | R1: C1 Rotor Bar | S1: C1 Foundation | T1: C1 House Power | U1: C1 Brake Horse Power | V1: C1 Current | W1: C1 Rated Capacity | X1: C1 Rated Active Power | Y1: C1 Rated Stator Voltage | Z1: C1 Rated Stator Current | AA1: C1 Rated Speed | AB1: C1 Rated Frequency | AC1: C2 Type/Mfg | AD1: C2 Manufacturer | AE1: C2 Speed | AF1: C2 Power | AG1: C2 Capacity | AH1: C2 Pressure | AI1: C2 Flow Rate | AJ1: C2 Bearing Type | AK1: C2 Inboard Bearing | AL1: C2 Onboard Bearing | AM1: C2 Total Blade | AN1: C2 NCR | AO1: C2 Ekstraction | AP1: C2 Stages | AQ1: C2 Governoor Type | AR1: Asset Category (Derived) | AS1: Source Page | AT1: Data Quality Note | AU1: Raw Specs (Audit) | AV1: Unit Group (Derived)
A2: REC-001 | B2: AST-001 | C2: Motor ID Fan 1#1 | D2: LJ10HNC10AN001-001 | E2: ISO 10816-3 (GROUP 1 RIGID) | F2: ISO 10816-3 (GROUP 1 RIGID) | G2: W37 | H2: 45544 | I2: NORMAL | J2: MOTOR | K2: FAN | L2: YKK4003-4 | M2: 985 | N2: 355 Kw | P2: NU324 | Q2: 6324 | R2: - | S2: Rigid | AK2: - | AL2: - | AR2: Fan | AS2: 1 | AU2: Type, Mfg : YKK4003-4 Type, Mfg. : | Speed : 985 Speed : | Power : 355 Kw Capacity : | Bearing Type : Bearing Type : | Inboard Bearing : NU324 Inboard Bearing : - | Outboard Bearing : 6324 Onboard Bearing : - | Rotor Bar : - Total Blade - | Foundation : Rigid | AV2: =IF(AS2<=36,"UNIT 1",IF(AS2<=70,"UNIT 2",IF(AS2<=110,"UNIT 3","COMMON"))) -> UNIT 1
A3: REC-002 | B3: AST-002 | C3: Motor ID Fan 2#1 | D3: LJ10HNC10AN002-001 | E3: ISO 10816-3 (GROUP 1 RIGID) | F3: ISO 10816-3 (GROUP 1 RIGID) | G3: W39 | H3: 45558 | I3: PREWARNING | J3: MOTOR | K3: FAN | L3: YKK4003-4 | M3: 985 | N3: 355 Kw | P3: NU324 | Q3: 6324 | R3: - | S3: Rigid | AK3: - | AL3: - | AR3: Fan | AS3: 3 | AU3: Type, Mfg : YKK4003-4 Type, Mfg. : | Speed : 985 Speed : | Power : 355 Kw Capacity : | Bearing Type : Bearing Type : | Inboard Bearing : NU324 Inboard Bearing : - | Outboard Bearing : 6324 Onboard Bearing : - | Rotor Bar : - Total Blade - | Foundation : Rigid | AV3: =IF(AS3<=36,"UNIT 1",IF(AS3<=70,"UNIT 2",IF(AS3<=110,"UNIT 3","COMMON"))) -> UNIT 1
A4: REC-003 | B4: AST-003 | C4: Motor Primary Air Fan 1#1 | D4: LJ10HLB10AN001-001 | E4: ISO 10816-3 (GROUP 1 RIGID) | F4: ISO 10816-3 (GROUP 1 RIGID) | G4: W37 | H4: 45544 | I4: NORMAL | J4: MOTOR | K4: FAN | L4: YKK 4001-4 | M4: 1480 r/min | N4: 280 kW | O4: Roller Bearing | P4: NU324 | Q4: 6224 | R4: - | S4: Rigid | AC4: QALG-217D | AE4: 1450 r/min | AH4: 13500 Pa | AI4: 50000 m2/h | AJ4: - | AK4: - | AL4: - | AM4: - | AR4: Fan | AS4: 5 | AU4: Type, Mfg : YKK 4001-4 Type, Mfg. : QALG-217D | Speed : 1480 r/min Speed : 1450 r/min | Power : 280 kW Pressure : 13500 Pa | Bearing Type : Roller Bearing Flow Rate : 50000 m2/h | Inboard Bearing : NU324 Bearing Type : - | Outboard Bearing : 6224 Inboard Bearing : - | Rotor Bar : - Onboard Bearing : - | Foundation : Rigid Total Blade : - | AV4: =IF(AS4<=36,"UNIT 1",IF(AS4<=70,"UNIT 2",IF(AS4<=110,"UNIT 3","COMMON"))) -> UNIT 1
A5: REC-004 | B5: AST-004 | C5: Motor Primary Air Fan 2#1 | D5: LJ10HLB10AN002-001 | E5: ISO 10816-3 (GROUP 1 RIGID) | F5: ISO 10816-3 (GROUP 1 RIGID) | G5: W39 | H5: 45558 | I5: NORMAL | J5: MOTOR | K5: FAN | L5: YKK 4001-4 | M5: 1480 r/min | N5: 280 kW | O5: Roller Bearing | P5: NU324 | Q5: 6224 | R5: - | S5: Rigid | AC5: QALG-217D | AE5: 1450 r/min | AH5: 13500 Pa | AI5: 50000 m2/h | AJ5: - | AK5: - | AL5: - | AM5: - | AR5: Fan | AS5: 7 | AU5: Type, Mfg : YKK 4001-4 Type, Mfg. : QALG-217D | Speed : 1480 r/min Speed : 1450 r/min | Power : 280 kW Pressure : 13500 Pa | Bearing Type : Roller Bearing Flow Rate : 50000 m2/h | Inboard Bearing : NU324 Bearing Type : - | Outboard Bearing : 6224 Inboard Bearing : - | Rotor Bar : - Onboard Bearing : - | Foundation : Rigid Total Blade : - | AV5: =IF(AS5<=36,"UNIT 1",IF(AS5<=70,"UNIT 2",IF(AS5<=110,"UNIT 3","COMMON"))) -> UNIT 1
A6: REC-005 | B6: AST-005 | C6: Motor Secondary Air Fan 1#1 | D6: LJ10HLB10AN003-001 | E6: ISO 10816-3 (GROUP 1 RIGID) | F6: ISO 10816-3 (GROUP 1 RIGID) | G6: W37 | H6: 45544 | I6: NORMAL | J6: MOTOR | K6: FAN | L6: YKK 4001-4 | M6: 1480 r/min | N6: 280 kW | O6: Roller Bearing | P6: NU324 | Q6: 6224 | R6: - | S6: Rigid | AC6: QALG-217D | AE6: 1450 r/min | AH6: 13500 Pa | AI6: 50000 m2/h | AJ6: - | AK6: - | AL6: - | AM6: - | AR6: Fan | AS6: 9 | AU6: Type, Mfg : YKK 4001-4 Type, Mfg. : QALG-217D | Speed : 1480 r/min Speed : 1450 r/min | Power : 280 kW Pressure : 13500 Pa | Bearing Type : Roller Bearing Flow Rate : 50000 m2/h | Inboard Bearing : NU324 Bearing Type : - | Outboard Bearing : 6224 Inboard Bearing : - | Rotor Bar : - Onboard Bearing : - | Foundation : Rigid Total Blade : - | AV6: =IF(AS6<=36,"UNIT 1",IF(AS6<=70,"UNIT 2",IF(AS6<=110,"UNIT 3","COMMON"))) -> UNIT 1
A7: REC-006 | B7: AST-006 | C7: Motor Secondary Air Fan 2#1 | D7: LJ10HLB10AN004-001 | E7: ISO 10816-3 (GROUP 1 RIGID) | F7: ISO 10816-3 (GROUP 1 RIGID) | G7: W39 | H7: 45558 | I7: PREWARNING | J7: MOTOR | K7: FAN | L7: YKK 4001-4 | M7: 1480 r/min | N7: 280 kW | O7: Roller Bearing | P7: NU324 | Q7: 6224 | R7: - | S7: Rigid | AC7: QALG-217D | AE7: 1450 r/min | AH7: 13500 Pa | AI7: 50000 m2/h | AJ7: - | AK7: - | AL7: - | AM7: - | AR7: Fan | AS7: 11 | AU7: Type, Mfg : YKK 4001-4 Type, Mfg. : QALG-217D | Speed : 1480 r/min Speed : 1450 r/min | Power : 280 kW Pressure : 13500 Pa | Bearing Type : Roller Bearing Flow Rate : 50000 m2/h | Inboard Bearing : NU324 Bearing Type : - | Outboard Bearing : 6224 Inboard Bearing : - | Rotor Bar : - Onboard Bearing : - | Foundation : Rigid Total Blade : - | AV7: =IF(AS7<=36,"UNIT 1",IF(AS7<=70,"UNIT 2",IF(AS7<=110,"UNIT 3","COMMON"))) -> UNIT 1
A8: REC-007 | B8: AST-007 | C8: Turbin-Generator#1 | D8: LJ10MAA10HB010-001 | E8: ISO 10816-2 | F8: ISO 10816-2 | G8: W37 | H8: 45544 | I8: NORMAL | J8: GENERATOR | K8: TURBINE | L8: China Changjiang Energy Corp. | W8: 37.5 MVA | X8: 30 MW | Y8: 6.3 kV Phase 3 Wire | AA8: 3000 r/min | AB8: 50 Hz | AD8: China Changjiang Energy Corp. | AE8: 3000 r/min | AN8: 30 MW | AO8: 6 | AP8: 19 | AQ8: Digital Electric Hidroulic (Woodard 505) | AR8: Turbine-Generator | AS8: 13 | AU8: Type, Mfg : China Changjiang Energy Corp. Manufacturer : China Changjiang Energy Corp. | Rated Capacity : 37.5 MVA Speed : 3000 r/min | Rated Active Power : 30 MW Ekstraction : 6 | Rated Stator Voltage : 6.3 kV Phase 3 Wire NCR : 30 MW | Rated Stator Current : Stages : 19 | Rated Speed : 3000 r/min | Governoor Type : Digital Electric Hidroulic (Woodard 505) | Rated Frequency : 50 Hz | : | AV8: =IF(AS8<=36,"UNIT 1",IF(AS8<=70,"UNIT 2",IF(AS8<=110,"UNIT 3","COMMON"))) -> UNIT 1
A9: REC-008 | B9: AST-008 | C9: Motor Condensat Pump 2#1 | D9: LJ10LCB10AP020-001 | E9: ISO 10816-3 (GROUP 2 RIGID) | F9: ISO 10816-3 (GROUP 2 RIGID) | G9: W36 | H9: 45537 | I9: PREWARNING | J9: MOTOR | K9: POMPA | L9: YLB 250-2-4 | M9: 1430 rpm | N9: 75 kW | O9: - | P9: - | Q9: - | R9: - | S9: Rigid | AC9: 5LDIN | AE9: 1480 rpm | AF9: 53 kW | AG9: 120 m3/h | AK9: - | AL9: - | AR9: Pump | AS9: 15 | AU9: Type, Mfg : YLB 250-2-4 Type, Mfg. : 5LDIN | Speed : 1430 rpm Speed : 1480 rpm | Power : 75 kW Power : 53 kW | Bearing Type : - Capacity : 120 m3/h | Inboard Bearing : - Type Bearing : | Outboard Bearing : - Inboard Bearing : - | Rotor Bar : - Onboard Bearing : - | Foundation : Rigid Total Impeler 5 | AV9: =IF(AS9<=36,"UNIT 1",IF(AS9<=70,"UNIT 2",IF(AS9<=110,"UNIT 3","COMMON"))) -> UNIT 1
A10: REC-009 | B10: AST-009 | C10: Motor Vacuum Pump 1#1 | D10: LJ10MAG10AP011-001 | E10: ISO 10816-3 (GROUP 2 RIGID) | F10: ISO 10816-3 (GROUP 2 RIGID) | G10: W39 | H10: 45558 | I10: NORMAL | J10: MOTOR | K10: POMPA | L10: Y2 - 250-6 | M10: 980 rpm | N10: 37 kW | R10: - | S10: Rigid | AK10: - | AL10: - | AR10: Pump | AS10: 17 | AU10: Type, Mfg : Y2 - 250-6 Type, Mfg. : | Speed : 980 rpm Speed : | Power : 37 kW Power : | Bearing Type : Capacity : | Inboard Bearing : Type Bearing : | Outboard Bearing : Inboard Bearing : - | Rotor Bar : - Onboard Bearing : - | Foundation : Rigid Total Impeler / blade 18 | AV10: =IF(AS10<=36,"UNIT 1",IF(AS10<=70,"UNIT 2",IF(AS10<=110,"UNIT 3","COMMON"))) -> UNIT 1
A11: REC-010 | B11: AST-010 | C11: Motor Vacuum Pump 2#1 | D11: LJ10MAG10AP012-001 | E11: ISO 10816-3 (GROUP 2 RIGID) | F11: ISO 10816-3 (GROUP 2 RIGID) | G11: W39 | H11: 45558 | I11: NORMAL | J11: MOTOR | K11: POMPA | L11: Y2 - 250-6 | M11: 980 rpm | N11: 37 kW | R11: - | S11: Rigid | AK11: - | AL11: - | AR11: Pump | AS11: 19 | AU11: Type, Mfg : Y2 - 250-6 Type, Mfg. : | Speed : 980 rpm Speed : | Power : 37 kW Power : | Bearing Type : Capacity : | Inboard Bearing : Type Bearing : | Outboard Bearing : Inboard Bearing : - | Rotor Bar : - Onboard Bearing : - | Foundation : Rigid Total Impeler 5 | AV11: =IF(AS11<=36,"UNIT 1",IF(AS11<=70,"UNIT 2",IF(AS11<=110,"UNIT 3","COMMON"))) -> UNIT 1
A12: REC-011 | B12: AST-011 | C12: Motor Boiler Feed Pump 1#1 | D12: LJ10LAC10AP001-001 | E12: ISO 10816-3 (GROUP 1 RIGID) | F12: ISO 10816-3 (GROUP 1 RIGID) | G12: W36 | H12: 45537 | I12: NORMAL | J12: MOTOR | K12: POMPA | L12: SY23372-1028, QINGJIANG | M12: 2980 rpm | N12: 1000 | P12: NU 224EC | Q12: 6224/C3 | R12: - | S12: Rigid | AC12: SHENYANG AST PUMP MANUFACTURING CO.,LTD | AE12: 2980 rpm | AG12: 140 | AK12: - | AL12: - | AR12: Pump | AS12: 21 | AU12: Type, Mfg : SY23372-1028, QINGJIANG Type, Mfg. : SHENYANG AST PUMP MANUFACTURING CO.,LTD | Speed : 2980 rpm Speed : 2980 rpm | Power : 1000 Capacity : 140 | Bearing Type : Bearing Type : | Inboard Bearing : NU 224EC Inboard Bearing : - | Outboard Bearing : 6224/C3 Onboard Bearing : - | Rotor Bar : - Total Blade - | Foundation : Rigid | AV12: =IF(AS12<=36,"UNIT 1",IF(AS12<=70,"UNIT 2",IF(AS12<=110,"UNIT 3","COMMON"))) -> UNIT 1
A13: REC-012 | B13: AST-012 | C13: Motor CCCWP 1#1 | D13: LJ10PGB10AP001-001 | E13: ISO 10816-3 (GROUP 2 RIGID) | F13: ISO 10816-3 (GROUP 2 RIGID) | G13: W37 | H13: 45545 | I13: PREWARNING | J13: MOTOR | K13: POMPA | L13: Y2 - 280-4 | M13: 980 rpm | N13: 75 kW | O13: - | P13: - | Q13: - | R13: - | S13: Rigid | AK13: - | AL13: - | AR13: Pump | AS13: 23 | AU13: Type, Mfg : Y2 - 280-4 Type, Mfg. : | Speed : 980 rpm Speed : | Power : 75 kW Power : | Bearing Type : - Capacity : | Inboard Bearing : - Type Bearing : | Outboard Bearing : - Inboard Bearing : - | Rotor Bar : - Onboard Bearing : - | Foundation : Rigid Total Impeler 5 | AV13: =IF(AS13<=36,"UNIT 1",IF(AS13<=70,"UNIT 2",IF(AS13<=110,"UNIT 3","COMMON"))) -> UNIT 1
A14: REC-013 | B14: AST-013 | C14: Motor CCCWP 2#1 | D14: LJ10PGB10AP002-001 | E14: ISO 10816-3 (GROUP 2 RIGID) | F14: ISO 10816-3 (GROUP 2 RIGID) | G14: W39 | H14: 45559 | I14: NORMAL | J14: MOTOR | K14: POMPA | L14: Y2 - 280-4 | M14: 980 rpm | N14: 75 kW | R14: - | S14: Rigid | AK14: - | AL14: - | AR14: Pump | AS14: 25 | AU14: Type, Mfg : Y2 - 280-4 Type, Mfg. : | Speed : 980 rpm Speed : | Power : 75 kW Power : | Bearing Type : Capacity : | Inboard Bearing : Type Bearing : | Outboard Bearing : Inboard Bearing : - | Rotor Bar : - Onboard Bearing : - | Foundation : Rigid Total Impeler 5 | AV14: =IF(AS14<=36,"UNIT 1",IF(AS14<=70,"UNIT 2",IF(AS14<=110,"UNIT 3","COMMON"))) -> UNIT 1
A15: REC-014 | B15: AST-014 | C15: Motor CWP 355 Kw 1#1 | D15: LJ10PAC10AP001-001 | E15: ISO 10816-3 (GROUP 1 RIGID)) | F15: ISO 10816-3 (GROUP 1 RIGID) | G15: W39 | H15: 45559 | I15: PREWARNING | J15: MOTOR | K15: POMPA | L15: YLKK400-6 | M15: 991 | N15: 315 | R15: - | S15: Rigid | AR15: Pump | AS15: 27 | AT15: Class dinormalisasi pada kolom terpisah; nilai sumber dipertahankan | AU15: Type, Mfg : YLKK400-6 Type, Mfg. : | Speed : 991 Speed : | Power : 315 Bearing Type : | Bearing Type : Inboard Bearing : | Inboard Bearing : Onboard Bearing : | Outboard Bearing : Total Blade : | Rotor Bar : - | Foundation : Rigid | AV15: =IF(AS15<=36,"UNIT 1",IF(AS15<=70,"UNIT 2",IF(AS15<=110,"UNIT 3","COMMON"))) -> UNIT 1
A16: REC-015 | B16: AST-015 | C16: Motor CWP 355 Kw 2#1 | D16: LJ10PAC10AP002-001 | E16: ISO 10816-3 (GROUP 1 RIGID)) | F16: ISO 10816-3 (GROUP 1 RIGID) | G16: W37 | H16: 45545 | I16: NORMAL | J16: MOTOR | K16: POMPA | L16: YLKK400-6 | M16: 991 | N16: 315 | R16: - | S16: Rigid | AR16: Pump | AS16: 29 | AT16: Class dinormalisasi pada kolom terpisah; nilai sumber dipertahankan | AU16: Type, Mfg : YLKK400-6 Type, Mfg. : | Speed : 991 Speed : | Power : 315 Bearing Type : | Bearing Type : Inboard Bearing : | Inboard Bearing : Onboard Bearing : | Outboard Bearing : Total Blade : | Rotor Bar : - | Foundation : Rigid | AV16: =IF(AS16<=36,"UNIT 1",IF(AS16<=70,"UNIT 2",IF(AS16<=110,"UNIT 3","COMMON"))) -> UNIT 1
A17: REC-016 | B17: AST-016 | C17: Motor BWRO 1#1 | D17: LJ10GCK10AP005-001 | E17: ISO 10816-3 (GROUP 2 RIGID) | F17: ISO 10816-3 (GROUP 2 RIGID) | G17: W37 | H17: 45545 | I17: PREWARNING | J17: MOTOR | K17: POMPA | L17: AEUBKG020015FMBP3 | M17: 2920 r/min | N17: 11 kw | O17: Roller Bearing | P17: 7309B | Q17: 6307C3 | R17: - | S17: Rigid | AC17: A96536974P11003 | AE17: 2920 r/min | AF17: 11 Kw | AG17: 21 m3/h | AK17: - | AL17: - | AR17: Pump | AS17: 32 | AU17: Type, Mfg : AEUBKG020015FMBP3 Type, Mfg. : A96536974P11003 | Speed : 2920 r/min Speed : 2920 r/min | Power : 11 kw Power : 11 Kw | Bearing Type : Roller Bearing Capacity : 21 m3/h | Inboard Bearing : 7309B Inboard Bearing : - | Outboard Bearing : 6307C3 Onboard Bearing : - | Rotor Bar : - Total Blade - | Foundation : Rigid | AV17: =IF(AS17<=36,"UNIT 1",IF(AS17<=70,"UNIT 2",IF(AS17<=110,"UNIT 3","COMMON"))) -> UNIT 1
A18: REC-017 | B18: AST-017 | C18: Motor SWRO 2#1 | D18: LJ10GCK10AP008-001 | E18: ISO 10816-3 (GROUP 2 RIGID) | F18: ISO 10816-3 (GROUP 2 RIGID) | G18: W39 | H18: 45559 | I18: NORMAL | J18: MOTOR | K18: POMPA | M18: 2970 r/min | N18: 75 | R18: - | S18: Rigid | AK18: - | AL18: - | AR18: Pump | AS18: 34 | AU18: Type, Mfg : Type, Mfg. : | Speed : 2970 r/min Speed : | Power : 75 Power : | Bearing Type : Capacity : | Inboard Bearing : Inboard Bearing : - | Outboard Bearing : Onboard Bearing : - | Rotor Bar : - Total Blade - | Foundation : Rigid | AV18: =IF(AS18<=36,"UNIT 1",IF(AS18<=70,"UNIT 2",IF(AS18<=110,"UNIT 3","COMMON"))) -> UNIT 1
A19: REC-018 | B19: AST-018 | C19: AC OIL PUMP UNIT 1 | E19: ISO 10816-3 (GROUP 2 RIGID) | F19: ISO 10816-3 (GROUP 2 RIGID) | G19: W38 | H19: 45551 | I19: PREWARNING | J19: MOTOR | K19: POMPA | L19: Y2 - 250-6 | M19: 980 rpm | N19: 37 kW | R19: - | S19: Rigid | AK19: - | AL19: - | AR19: Pump | AS19: 36 | AT19: KKS kosong pada sumber PDF | AU19: Type, Mfg : Y2 - 250-6 Type, Mfg. : | Speed : 980 rpm Speed : | Power : 37 kW Power : | Bearing Type : Capacity : | Inboard Bearing : Type Bearing : | Outboard Bearing : Inboard Bearing : - | Rotor Bar : - Onboard Bearing : - | Foundation : Rigid Total Impeler 5 | AV19: =IF(AS19<=36,"UNIT 1",IF(AS19<=70,"UNIT 2",IF(AS19<=110,"UNIT 3","COMMON"))) -> UNIT 1
A20: REC-019 | B20: AST-019 | C20: Motor ID Fan 1#2 | D20: LJ20HNC10AN001-001 | E20: ISO 10816-3 (GROUP 1 RIGID) | F20: ISO 10816-3 (GROUP 1 RIGID) | G20: W39 | H20: 45559 | I20: NORMAL | J20: MOTOR | K20: FAN | L20: YKK4003-4 | M20: 985 | N20: 355 Kw | P20: NU324 | Q20: 6324 | R20: - | S20: Rigid | AK20: - | AL20: - | AR20: Fan | AS20: 38 | AU20: Type, Mfg : YKK4003-4 Type, Mfg. : | Speed : 985 Speed : | Power : 355 Kw Capacity : | Bearing Type : Bearing Type : | Inboard Bearing : NU324 Inboard Bearing : - | Outboard Bearing : 6324 Onboard Bearing : - | Rotor Bar : - Total Blade - | Foundation : Rigid | AV20: =IF(AS20<=36,"UNIT 1",IF(AS20<=70,"UNIT 2",IF(AS20<=110,"UNIT 3","COMMON"))) -> UNIT 2
A21: REC-020 | B21: AST-020 | C21: Motor ID Fan 2#2 | D21: LJ20HNC10AN002-001 | E21: ISO 10816-3 (GROUP 1 RIGID) | F21: ISO 10816-3 (GROUP 1 RIGID) | G21: W37 | H21: 45545 | I21: PREWARNING | J21: MOTOR | K21: FAN | L21: YKK4003-4 | M21: 985 | N21: 355 Kw | P21: NU324 | Q21: 6324 | R21: - | S21: Rigid | AK21: - | AL21: - | AR21: Fan | AS21: 40 | AU21: Type, Mfg : YKK4003-4 Type, Mfg. : | Speed : 985 Speed : | Power : 355 Kw Capacity : | Bearing Type : Bearing Type : | Inboard Bearing : NU324 Inboard Bearing : - | Outboard Bearing : 6324 Onboard Bearing : - | Rotor Bar : - Total Blade - | Foundation : Rigid | AV21: =IF(AS21<=36,"UNIT 1",IF(AS21<=70,"UNIT 2",IF(AS21<=110,"UNIT 3","COMMON"))) -> UNIT 2
A22: REC-021 | B22: AST-021 | C22: Motor Primary Air Fan 1#2 | D22: LJ20HLB10AN001-001 | E22: ISO 10816-3 (GROUP 1 RIGID) | F22: ISO 10816-3 (GROUP 1 RIGID) | G22: W39 | H22: 45560 | I22: NORMAL | J22: MOTOR | K22: FAN | L22: YKK 4001-4 | M22: 1480 r/min | N22: 280 kW | O22: Roller Bearing | P22: NU324 | Q22: 6224 | R22: - | S22: Rigid | AC22: QALG-217D | AE22: 1450 r/min | AH22: 13500 Pa | AI22: 50000 m2/h | AJ22: - | AK22: - | AL22: - | AM22: - | AR22: Fan | AS22: 42 | AU22: Type, Mfg : YKK 4001-4 Type, Mfg. : QALG-217D | Speed : 1480 r/min Speed : 1450 r/min | Power : 280 kW Pressure : 13500 Pa | Bearing Type : Roller Bearing Flow Rate : 50000 m2/h | Inboard Bearing : NU324 Bearing Type : - | Outboard Bearing : 6224 Inboard Bearing : - | Rotor Bar : - Onboard Bearing : - | Foundation : Rigid Total Blade : - | AV22: =IF(AS22<=36,"UNIT 1",IF(AS22<=70,"UNIT 2",IF(AS22<=110,"UNIT 3","COMMON"))) -> UNIT 2
A23: REC-022 | B23: AST-022 | C23: Motor Primary Air Fan 2#2 | D23: LJ20HLB10AN002-001 | E23: ISO 10816-3 (GROUP 1 RIGID) | F23: ISO 10816-3 (GROUP 1 RIGID) | G23: W37 | H23: 45546 | I23: NORMAL | J23: MOTOR | K23: FAN | L23: YKK 4001-4 | M23: 1480 r/min | N23: 280 kW | O23: Roller Bearing | P23: NU324 | Q23: 6224 | R23: - | S23: Rigid | AC23: QALG-217D | AE23: 1450 r/min | AH23: 13500 Pa | AI23: 50000 m2/h | AJ23: - | AK23: - | AL23: - | AM23: - | AR23: Fan | AS23: 44 | AU23: Type, Mfg : YKK 4001-4 Type, Mfg. : QALG-217D | Speed : 1480 r/min Speed : 1450 r/min | Power : 280 kW Pressure : 13500 Pa | Bearing Type : Roller Bearing Flow Rate : 50000 m2/h | Inboard Bearing : NU324 Bearing Type : - | Outboard Bearing : 6224 Inboard Bearing : - | Rotor Bar : - Onboard Bearing : - | Foundation : Rigid Total Blade : - | AV23: =IF(AS23<=36,"UNIT 1",IF(AS23<=70,"UNIT 2",IF(AS23<=110,"UNIT 3","COMMON"))) -> UNIT 2
A24: REC-023 | B24: AST-023 | C24: Motor Secondary Air Fan 1#2 | D24: LJ20HLB10AN003-001 | E24: ISO 10816-3 (GROUP 1 RIGID) | F24: ISO 10816-3 (GROUP 1 RIGID) | G24: W39 | H24: 45560 | I24: PREWARNING | J24: MOTOR | K24: FAN | L24: YKK 4001-4 | M24: 1480 r/min | N24: 280 kW | O24: Roller Bearing | P24: NU324 | Q24: 6224 | R24: - | S24: Rigid | AC24: QALG-217D | AE24: 1450 r/min | AH24: 13500 Pa | AI24: 50000 m2/h | AJ24: - | AK24: - | AL24: - | AM24: - | AR24: Fan | AS24: 46 | AU24: Type, Mfg : YKK 4001-4 Type, Mfg. : QALG-217D | Speed : 1480 r/min Speed : 1450 r/min | Power : 280 kW Pressure : 13500 Pa | Bearing Type : Roller Bearing Flow Rate : 50000 m2/h | Inboard Bearing : NU324 Bearing Type : - | Outboard Bearing : 6224 Inboard Bearing : - | Rotor Bar : - Onboard Bearing : - | Foundation : Rigid Total Blade : - | AV24: =IF(AS24<=36,"UNIT 1",IF(AS24<=70,"UNIT 2",IF(AS24<=110,"UNIT 3","COMMON"))) -> UNIT 2
A25: REC-024 | B25: AST-024 | C25: Motor Secondary Air Fan 2#2 | D25: LJ20HLB10AN004-001 | E25: ISO 10816-3 (GROUP 1 RIGID) | F25: ISO 10816-3 (GROUP 1 RIGID) | G25: W37 | H25: 45546 | I25: NORMAL | J25: MOTOR | K25: FAN | L25: YKK 4001-4 | M25: 1480 r/min | N25: 280 kW | O25: Roller Bearing | P25: NU324 | Q25: 6224 | R25: - | S25: Rigid | AC25: QALG-217D | AE25: 1450 r/min | AH25: 13500 Pa | AI25: 50000 m2/h | AJ25: - | AK25: - | AL25: - | AM25: - | AR25: Fan | AS25: 48 | AU25: Type, Mfg : YKK 4001-4 Type, Mfg. : QALG-217D | Speed : 1480 r/min Speed : 1450 r/min | Power : 280 kW Pressure : 13500 Pa | Bearing Type : Roller Bearing Flow Rate : 50000 m2/h | Inboard Bearing : NU324 Bearing Type : - | Outboard Bearing : 6224 Inboard Bearing : - | Rotor Bar : - Onboard Bearing : - | Foundation : Rigid Total Blade : - | AV25: =IF(AS25<=36,"UNIT 1",IF(AS25<=70,"UNIT 2",IF(AS25<=110,"UNIT 3","COMMON"))) -> UNIT 2
A26: REC-025 | B26: AST-025 | C26: Turbin-Generator#2 | D26: LJ20MAA10HB010-001 | E26: ISO 10816-2 | F26: ISO 10816-2 | G26: W39 | H26: 45560 | I26: PREWARNING | J26: GENERATOR | K26: TURBINE | L26: China Changjiang Energy Corp. | W26: 37.5 MVA | X26: 30 MW | Y26: 6.3 kV Phase 3 Wire | AA26: 3000 r/min | AB26: 50 Hz | AD26: China Changjiang Energy Corp. | AE26: 3000 r/min | AN26: 30 MW | AO26: 6 | AP26: 19 | AQ26: Digital Electric Hidroulic (Woodard 505) | AR26: Turbine-Generator | AS26: 50 | AU26: Type, Mfg : China Changjiang Energy Corp. Manufacturer : China Changjiang Energy Corp. | Rated Capacity : 37.5 MVA Speed : 3000 r/min | Rated Active Power : 30 MW Ekstraction : 6 | Rated Stator Voltage : 6.3 kV Phase 3 Wire NCR : 30 MW | Rated Stator Current : Stages : 19 | Rated Speed : 3000 r/min | Governoor Type : Digital Electric Hidroulic (Woodard 505) | Rated Frequency : 50 Hz | : | AV26: =IF(AS26<=36,"UNIT 1",IF(AS26<=70,"UNIT 2",IF(AS26<=110,"UNIT 3","COMMON"))) -> UNIT 2
A27: REC-026 | B27: AST-026 | C27: Motor Condensat Pump 1#2 | D27: LJ20LCB10AP010-001 | E27: ISO 10816-3 (GROUP 2 RIGID) | F27: ISO 10816-3 (GROUP 2 RIGID) | G27: W36 | H27: 45537 | I27: NORMAL | J27: MOTOR | K27: POMPA | L27: YLB 250-2-4 | M27: 1430 rpm | N27: 75 kW | O27: - | P27: - | Q27: - | R27: - | S27: Rigid | AK27: - | AL27: - | AR27: Pump | AS27: 52 | AU27: Type, Mfg : YLB 250-2-4 Type, Mfg. : | Speed : 1430 rpm Speed : | Power : 75 kW Power : | Bearing Type : - Capacity : | Inboard Bearing : - Type Bearing : | Outboard Bearing : - Inboard Bearing : - | Rotor Bar : - Onboard Bearing : - | Foundation : Rigid Total Impeler 5 | AV27: =IF(AS27<=36,"UNIT 1",IF(AS27<=70,"UNIT 2",IF(AS27<=110,"UNIT 3","COMMON"))) -> UNIT 2
A28: REC-027 | B28: AST-027 | C28: Motor Vacuum Pump 1#2 | D28: LJ20MAG10AP011-001 | E28: ISO 10816-3 (GROUP 2 RIGID) | F28: ISO 10816-3 (GROUP 2 RIGID) | G28: W39 | H28: 45561 | I28: PREWARNING | J28: MOTOR | K28: POMPA | L28: Y2 - 250-6 | M28: 980 rpm | N28: 37 kW | R28: - | S28: Rigid | AK28: - | AL28: - | AR28: Pump | AS28: 54 | AU28: Type, Mfg : Y2 - 250-6 Type, Mfg. : | Speed : 980 rpm Speed : | Power : 37 kW Power : | Bearing Type : Capacity : | Inboard Bearing : Type Bearing : | Outboard Bearing : Inboard Bearing : - | Rotor Bar : - Onboard Bearing : - | Foundation : Rigid Total Impeler | AV28: =IF(AS28<=36,"UNIT 1",IF(AS28<=70,"UNIT 2",IF(AS28<=110,"UNIT 3","COMMON"))) -> UNIT 2
A29: REC-028 | B29: AST-028 | C29: Motor Vacuum Pump 2#2 | D29: LJ20MAG10AP012-001 | E29: ISO 10816-3 (GROUP 2 RIGID) | F29: ISO 10816-3 (GROUP 2 RIGID) | G29: W39 | H29: 45561 | I29: PREWARNING | J29: MOTOR | K29: POMPA | L29: Y2 - 250-6 | M29: 980 rpm | N29: 37 kW | R29: - | S29: Rigid | AK29: - | AL29: - | AR29: Pump | AS29: 56 | AU29: Type, Mfg : Y2 - 250-6 Type, Mfg. : | Speed : 980 rpm Speed : | Power : 37 kW Power : | Bearing Type : Capacity : | Inboard Bearing : Type Bearing : | Outboard Bearing : Inboard Bearing : - | Rotor Bar : - Onboard Bearing : - | Foundation : Rigid Total Impeler 5 | AV29: =IF(AS29<=36,"UNIT 1",IF(AS29<=70,"UNIT 2",IF(AS29<=110,"UNIT 3","COMMON"))) -> UNIT 2
A30: REC-029 | B30: AST-029 | C30: Motor Boiler Feed Pump 2#2 | D30: LJ20LAC10AP002-001 | E30: ISO 10816-3 (GROUP 1 RIGID) | F30: ISO 10816-3 (GROUP 1 RIGID) | G30: W36 | H30: 45537 | I30: PREWARNING | J30: MOTOR | K30: FAN | L30: SY23372-1028, QINGJIANG | M30: 2980 rpm | N30: 1000 | P30: NU 224EC | Q30: 6224/C3 | R30: - | S30: Rigid | AC30: SHENYANG AST PUMP MANUFACTURING CO.,LTD | AE30: 2980 rpm | AG30: 140 | AK30: - | AL30: - | AR30: Pump | AS30: 58 | AU30: Type, Mfg : SY23372-1028, QINGJIANG Type, Mfg. : SHENYANG AST PUMP MANUFACTURING CO.,LTD | Speed : 2980 rpm Speed : 2980 rpm | Power : 1000 Capacity : 140 | Bearing Type : Bearing Type : | Inboard Bearing : NU 224EC Inboard Bearing : - | Outboard Bearing : 6224/C3 Onboard Bearing : - | Rotor Bar : - Total Blade - | Foundation : Rigid | AV30: =IF(AS30<=36,"UNIT 1",IF(AS30<=70,"UNIT 2",IF(AS30<=110,"UNIT 3","COMMON"))) -> UNIT 2
A31: REC-030 | B31: AST-030 | C31: Motor CCCWP 1#2 | D31: LJ20PGB10AP001-001 | E31: ISO 10816-3 (GROUP 2 RIGID) | F31: ISO 10816-3 (GROUP 2 RIGID) | G31: W39 | H31: 45561 | I31: PREWARNING | J31: MOTOR | K31: POMPA | L31: Y2 - 280-4 | M31: 980 rpm | N31: 75 kW | O31: - | P31: - | Q31: - | R31: - | S31: Rigid | AK31: - | AL31: - | AR31: Pump | AS31: 60 | AU31: Type, Mfg : Y2 - 280-4 Type, Mfg. : | Speed : 980 rpm Speed : | Power : 75 kW Power : | Bearing Type : - Capacity : | Inboard Bearing : - Type Bearing : | Outboard Bearing : - Inboard Bearing : - | Rotor Bar : - Onboard Bearing : - | Foundation : Rigid Total Impeler 5 | AV31: =IF(AS31<=36,"UNIT 1",IF(AS31<=70,"UNIT 2",IF(AS31<=110,"UNIT 3","COMMON"))) -> UNIT 2
A32: REC-031 | B32: AST-031 | C32: Motor CCCWP 2#2 | D32: LJ20PGB10AP002-001 | E32: ISO 10816-3 (GROUP 2 RIGID) | F32: ISO 10816-3 (GROUP 2 RIGID) | G32: W39 | H32: 45561 | I32: PREWARNING | J32: MOTOR | K32: POMPA | L32: Y2 - 280-4 | M32: 980 rpm | N32: 75 kW | R32: - | S32: Rigid | AK32: - | AL32: - | AR32: Pump | AS32: 62 | AU32: Type, Mfg : Y2 - 280-4 Type, Mfg. : | Speed : 980 rpm Speed : | Power : 75 kW Power : | Bearing Type : Capacity : | Inboard Bearing : Type Bearing : | Outboard Bearing : Inboard Bearing : - | Rotor Bar : - Onboard Bearing : - | Foundation : Rigid Total Impeler 5 | AV32: =IF(AS32<=36,"UNIT 1",IF(AS32<=70,"UNIT 2",IF(AS32<=110,"UNIT 3","COMMON"))) -> UNIT 2
A33: REC-032 | B33: AST-032 | C33: Motor CWP 355 Kw 1#2 | D33: LJ20PAC10AP001-001 | E33: ISO 10816-3 (GROUP 1 RIGID)) | F33: ISO 10816-3 (GROUP 1 RIGID) | G33: W38 | H33: 45552 | I33: NORMAL | J33: MOTOR | K33: POMPA | L33: YLKK400-6 | M33: 991 | N33: 315 | R33: - | S33: Rigid | AR33: Pump | AS33: 64 | AT33: Class dinormalisasi pada kolom terpisah; nilai sumber dipertahankan | AU33: Type, Mfg : YLKK400-6 Type, Mfg. : | Speed : 991 Speed : | Power : 315 Bearing Type : | Bearing Type : Inboard Bearing : | Inboard Bearing : Onboard Bearing : | Outboard Bearing : Total Blade : | Rotor Bar : - | Foundation : Rigid | AV33: =IF(AS33<=36,"UNIT 1",IF(AS33<=70,"UNIT 2",IF(AS33<=110,"UNIT 3","COMMON"))) -> UNIT 2
A34: REC-033 | B34: AST-033 | C34: Motor CWP 355 Kw 2#2 | D34: LJ20PAC10AP002-001 | E34: ISO 10816-3 (GROUP 1 RIGID)) | F34: ISO 10816-3 (GROUP 1 RIGID) | G34: W36 | H34: 45537 | I34: NORMAL | J34: MOTOR | K34: POMPA | L34: YLKK400-6 | M34: 991 | N34: 315 | R34: - | S34: Rigid | AR34: Pump | AS34: 66 | AT34: Class dinormalisasi pada kolom terpisah; nilai sumber dipertahankan | AU34: Type, Mfg : YLKK400-6 Type, Mfg. : | Speed : 991 Speed : | Power : 315 Bearing Type : | Bearing Type : Inboard Bearing : | Inboard Bearing : Onboard Bearing : | Outboard Bearing : Total Blade : | Rotor Bar : - | Foundation : Rigid | AV34: =IF(AS34<=36,"UNIT 1",IF(AS34<=70,"UNIT 2",IF(AS34<=110,"UNIT 3","COMMON"))) -> UNIT 2
A35: REC-034 | B35: AST-034 | C35: ACA OIL PUMP UNIT 2 | E35: ISO 10816-3 (GROUP 2 RIGID) | F35: ISO 10816-3 (GROUP 2 RIGID) | G35: W38 | H35: 45552 | I35: PREWARNING | J35: MOTOR | K35: POMPA | L35: Y2 - 250-6 | M35: 980 rpm | N35: 37 kW | R35: - | S35: Rigid | AK35: - | AL35: - | AR35: Pump | AS35: 68 | AT35: KKS kosong pada sumber PDF; Metadata aset yang sama muncul pada halaman 68, 70 | AU35: Type, Mfg : Y2 - 250-6 Type, Mfg. : | Speed : 980 rpm Speed : | Power : 37 kW Power : | Bearing Type : Capacity : | Inboard Bearing : Type Bearing : | Outboard Bearing : Inboard Bearing : - | Rotor Bar : - Onboard Bearing : - | Foundation : Rigid Total Impeler 5 | AV35: =IF(AS35<=36,"UNIT 1",IF(AS35<=70,"UNIT 2",IF(AS35<=110,"UNIT 3","COMMON"))) -> UNIT 2
A36: REC-035 | B36: AST-034 | C36: ACA OIL PUMP UNIT 2 | E36: ISO 10816-3 (GROUP 2 RIGID) | F36: ISO 10816-3 (GROUP 2 RIGID) | G36: W38 | H36: 45552 | I36: PREWARNING | J36: MOTOR | K36: POMPA | L36: Y2 - 250-6 | M36: 980 rpm | N36: 37 kW | R36: - | S36: Rigid | AK36: - | AL36: - | AR36: Pump | AS36: 70 | AT36: KKS kosong pada sumber PDF; Metadata aset yang sama muncul pada halaman 68, 70 | AU36: Type, Mfg : Y2 - 250-6 Type, Mfg. : | Speed : 980 rpm Speed : | Power : 37 kW Power : | Bearing Type : Capacity : | Inboard Bearing : Type Bearing : | Outboard Bearing : Inboard Bearing : - | Rotor Bar : - Onboard Bearing : - | Foundation : Rigid Total Impeler 5 | AV36: =IF(AS36<=36,"UNIT 1",IF(AS36<=70,"UNIT 2",IF(AS36<=110,"UNIT 3","COMMON"))) -> UNIT 2
A37: REC-036 | B37: AST-035 | C37: Motor ID Fan 1#3 | D37: LJ03HNC10AN001-001 | E37: ISO 10816-3 (GROUP 1 RIGID) | F37: ISO 10816-3 (GROUP 1 RIGID) | G37: W38 | H37: 45552 | I37: NORMAL | J37: MOTOR | K37: FAN | L37: YKK 4504-6 | M37: 990 | N37: 450 | O37: Roller Bearing | P37: NU228E/C3 | Q37: 6226/C3 | R37: - | S37: Rigid | AC37: 25 SB-P | AE37: 2980 r/min | AG37: 165 m3/h | AJ37: Journal Bearing | AK37: - | AL37: - | AR37: Fan | AS37: 72 | AU37: Type, Mfg : YKK 4504-6 Type, Mfg. : 25 SB-P | Speed : 990 Speed : 2980 r/min | Power : 450 Capacity : 165 m3/h | Bearing Type : Roller Bearing Bearing Type : Journal Bearing | Inboard Bearing : NU228E/C3 Inboard Bearing : - | Outboard Bearing : 6226/C3 Onboard Bearing : - | Rotor Bar : - Total Blade - | Foundation : Rigid | AV37: =IF(AS37<=36,"UNIT 1",IF(AS37<=70,"UNIT 2",IF(AS37<=110,"UNIT 3","COMMON"))) -> UNIT 3
A38: REC-037 | B38: AST-036 | C38: Motor ID Fan 2#3 | D38: LJ03HNC20AN001-001 | E38: ISO 10816-3 (GROUP 1 RIGID) | F38: ISO 10816-3 (GROUP 1 RIGID) | G38: W36 | H38: 45538 | I38: NORMAL | J38: MOTOR | K38: FAN | L38: YKK 4504-6 | M38: 990 | N38: 450 | O38: Roller Bearing | P38: NU228E/C3 | Q38: 6226/C3 | R38: - | S38: Rigid | AC38: 25 SB-P | AE38: 2980 r/min | AG38: 165 m3/h | AJ38: Journal Bearing | AK38: - | AL38: - | AR38: Fan | AS38: 74 | AU38: Type, Mfg : YKK 4504-6 Type, Mfg. : 25 SB-P | Speed : 990 Speed : 2980 r/min | Power : 450 Capacity : 165 m3/h | Bearing Type : Roller Bearing Bearing Type : Journal Bearing | Inboard Bearing : NU228E/C3 Inboard Bearing : - | Outboard Bearing : 6226/C3 Onboard Bearing : - | Rotor Bar : - Total Blade - | Foundation : Rigid | AV38: =IF(AS38<=36,"UNIT 1",IF(AS38<=70,"UNIT 2",IF(AS38<=110,"UNIT 3","COMMON"))) -> UNIT 3
A39: REC-038 | B39: AST-037 | C39: Motor Primary Air Fan#3 | D39: LJ03HLB10AN001-001 | E39: ISO 10816-3 (GROUP 1 RIGID) | F39: ISO 10816-3 (GROUP 1 RIGID) | G39: W36 | H39: 45538 | I39: PREWARNING | J39: MOTOR | K39: FAN | L39: YKK 4504-4 | M39: 1490 | N39: 630 | O39: Roller Bearing | P39: NU226E/C3 | Q39: 6228/C3 | R39: - | S39: Rigid | AC39: G6-30 19.50 | AE39: 1485 r/min | AF39: 630 Kw | AI39: 400871 m2/h | AJ39: Journal Bearing | AK39: - | AL39: - | AM39: - | AR39: Fan | AS39: 76 | AU39: Type, Mfg : YKK 4504-4 Type, Mfg. : G6-30 19.50 | Speed : 1490 Speed : 1485 r/min | Power : 630 Power : 630 Kw | Bearing Type : Roller Bearing Flow Rate : 400871 m2/h | Inboard Bearing : NU226E/C3 Bearing Type : Journal Bearing | Outboard Bearing : 6228/C3 Inboard Bearing : - | Rotor Bar : - Onboard Bearing : - | Foundation : Rigid Total Blade : - | AV39: =IF(AS39<=36,"UNIT 1",IF(AS39<=70,"UNIT 2",IF(AS39<=110,"UNIT 3","COMMON"))) -> UNIT 3
A40: REC-039 | B40: AST-038 | C40: Motor Secondary Air Fan#3 | D40: LJ03HLB20AN001-001 | E40: ISO 10816-3 (GROUP 1 RIGID) | F40: ISO 10816-3 (GROUP 1 RIGID) | G40: W39 | H40: 45561 | I40: PREWARNING | J40: MOTOR | K40: FAN | L40: YKK 4504-4 | M40: 1485 | N40: 400 | O40: Roller Bearing | P40: NU224EC | Q40: 6224/C3 | R40: - | S40: Rigid | AC40: G6-40 16.20 | AE40: 1485 r/min | AF40: 400 Kw | AI40: 87120 m2/h | AJ40: Journal Bearing | AK40: - | AL40: - | AM40: - | AR40: Fan | AS40: 78 | AU40: Type, Mfg : YKK 4504-4 Type, Mfg. : G6-40 16.20 | Speed : 1485 Speed : 1485 r/min | Power : 400 Power : 400 Kw | Bearing Type : Roller Bearing Flow Rate : 87120 m2/h | Inboard Bearing : NU224EC Bearing Type : Journal Bearing | Outboard Bearing : 6224/C3 Inboard Bearing : - | Rotor Bar : - Onboard Bearing : - | Foundation : Rigid Total Blade : - | AV40: =IF(AS40<=36,"UNIT 1",IF(AS40<=70,"UNIT 2",IF(AS40<=110,"UNIT 3","COMMON"))) -> UNIT 3
...

Sheet Data_Quality
A1: Issue | B1: Record/Asset | C1: Equipment / Source Value | D1: KKS | E1: Source Page(s) | F1: Keterangan
A2: KKS kosong | B2: REC-018 | C2: AC OIL PUMP UNIT 1 | E2: 36 | F2: KKS memang kosong pada sumber PDF
A3: KKS kosong | B3: REC-034 | C3: ACA OIL PUMP UNIT 2 | E3: 68 | F3: KKS memang kosong pada sumber PDF
A4: KKS kosong | B4: REC-035 | C4: ACA OIL PUMP UNIT 2 | E4: 70 | F4: KKS memang kosong pada sumber PDF
A5: KKS kosong | B5: REC-041 | C5: Turbin-Generator#3 | E5: 82 | F5: KKS memang kosong pada sumber PDF
A6: KKS kosong | B6: REC-051 | C6: FIRE FIGHTING JOCKEY PUMP 3B | E6: 102 | F6: KKS memang kosong pada sumber PDF
A7: KKS kosong | B7: REC-052 | C7: FIRE FIGHTING PUMP WITH MOTOR UNIT 3 | E7: 104 | F7: KKS memang kosong pada sumber PDF
A8: KKS kosong | B8: REC-053 | C8: FIRE FIGHTING PUMP WITH DIESEL UNIT 3 | E8: 106 | F8: KKS memang kosong pada sumber PDF
A9: KKS kosong | B9: REC-054 | C9: AC OIL PUMP UNIT 3 | E9: 108 | F9: KKS memang kosong pada sumber PDF
A10: KKS kosong | B10: REC-055 | C10: JACKING OIL PUMP 3A | E10: 110 | F10: KKS memang kosong pada sumber PDF
A11: Metadata aset berulang | B11: AST-034 | C11: ACA OIL PUMP UNIT 2 | E11: 68, 70 | F11: Report record dipertahankan terpisah
A12: Spelling class sumber | B12: - | C12: ISO 10816-3 (GROUP 1 RIGID)) | E12: 27 | F12: Normalized: ISO 10816-3 (GROUP 1 RIGID)
A13: Spelling class sumber | B13: - | C13: ISO 10816-3 (GROUP 2 EXLIBLE) | E13: 112 | F13: Normalized: ISO 10816-3 (GROUP 2 FLEXIBLE)
... A15: Spelling class sumber | B15: - | C15: ISO 10816-3 (GROUP 2 FLECXBLE) | E15: 132 | F15: Normalized: ISO 10816-3 (GROUP 2 FLEXIBLE)

Sheet Field_Dictionary
A1: Field | B1: Jenis | C1: Keterangan
A2: Asset ID | B2: Derived | C2: ID internal AST-xxx untuk identitas aset berdasarkan Equipment + KKS.
A3: Record ID | B3: Derived | C3: ID REC-xxx untuk setiap halaman DETAIL REPORT VIBRASI.
A4: Equipment | B4: Source | C4: Nama EQUIPMENT persis dari PDF.
A5: KKS | B5: Source | C5: Kode KKS; blank dipertahankan bila sumber kosong.
A6: Equipment Class (Source) | B6: Source | C6: Class/standard persis dari PDF, termasuk spelling/typo.
A7: Equipment Class (Normalized) | B7: Derived | C7: Normalisasi spelling class agar mudah difilter; tidak mengganti nilai sumber.
A8: PM Week | B8: Source | C8: PM WEEK pada report.
A9: Measurement Date | B9: Source | C9: TGL PENGUKURAN pada report.
A10: Status Vibrasi | B10: Source | C10: NORMAL / PREWARNING / WARNING / ALARM pada report.
