Workbook

Sheet RESUME
D1: PT PLN INDONESIA POWER | L1: No. Dok | M1: : FORM.JRG.F.05.001
D2: UBP JERANJANG | L2: Tgl Terbit | M2: : 1 Sep 2016
D3: BIDANG RCBM | L3: Rev | M3: : 00
D4: LAPORAN PDM | L4: Hal | M4: :
B6: LAPORAN IR THERMOGRAPHY BULAN JULI 2026 UNIT BISNIS PEMBANGKITAN JERANJANG
B9: UNIT | D9: STATUS IR THERMOGRAPHY
D10: NORMAL | E10: LOW | F10: MEDIUM | G10: HIGH | H10: CRITICAL | I10: STANDBY | K10: Keterangan :
B11: UNIT 1 | D11: =COUNTIF(SUMMARY!E3:F27,"Normal") -> 10 | E11: =COUNTIF(SUMMARY!E3:F27,"Low") -> 7 | F11: =COUNTIF(SUMMARY!E3:F27,"MEDIUM") -> 4 | G11: =COUNTIF(SUMMARY!E3:F27,"HIGH") -> 0 | H11: =COUNTIF(SUMMARY!E3:F27,"CRITICAL") -> 0 | I11: =COUNTIF(SUMMARY!E3:F27,"STD BY") -> 4 | K11: NORMAL | L11: = Kondisi baik
B12: UNIT 2 | D12: =COUNTIF(SUMMARY!E28:F46,"Normal") -> 11 | E12: =COUNTIF(SUMMARY!E28:F46,"Low") -> 4 | F12: =COUNTIF(SUMMARY!E28:F46,"MEDIUM") -> 1 | G12: =COUNTIF(SUMMARY!E28:F46,"HIGH") -> 0 | H12: =COUNTIF(SUMMARY!E28:F46,"CRITICAL") -> 0 | I12: =COUNTIF(SUMMARY!E28:F46,"STD BY") -> 3 | K12: LOW | L12: = Periksa saat pemeliharaan
B13: UNIT 3 | D13: =COUNTIF(SUMMARY!E47:F80,"Normal") -> 18 | E13: =COUNTIF(SUMMARY!E47:F80,"Low") -> 4 | F13: =COUNTIF(SUMMARY!E47:F80,"MEDIUM") -> 4 | G13: =COUNTIF(SUMMARY!E47:F80,"HIGH") -> 0 | H13: =COUNTIF(SUMMARY!E47:F80,"CRITICAL") -> 0 | I13: =COUNTIF(SUMMARY!E47:F80,"STD BY") -> 7 | K13: MEDIUM | L13: = Rencana pebaikan (Max. 30 hari)
B14: COAL HANDLING | D14: =COUNTIF(SUMMARY!E81:F98,"Normal") -> 10 | E14: =COUNTIF(SUMMARY!E81:F98,"Low") -> 0 | F14: =COUNTIF(SUMMARY!E81:F98,"MEDIUM") -> 2 | G14: =COUNTIF(SUMMARY!E81:F98,"HIGH") -> 0 | H14: =COUNTIF(SUMMARY!E81:F98,"CRITICAL") -> 0 | I14: =COUNTIF(SUMMARY!E81:F98,"STD BY") -> 6 | K14: HIGH | L14: = Perbaikan segera
B15: TOTAL | D15: =SUM(D11:D14) -> 49 | E15: =SUM(E11:E14) -> 15 | F15: =SUM(F11:F14) -> 11 | G15: =SUM(G11:G14) -> 0 | H15: =SUM(H11:H14) -> 0 | I15: =SUM(I11:I14) -> 20 | J15: =SUM(D15:I15) -> 95 | K15: CRITICAL | L15: = Kondisi darurat
B16: PERSENTASE (%) | D16: =D15/J15*100 -> 51.578947 | E16: =E15/J15*100 -> 15.789474 | F16: =F15/J15*100 -> 11.578947 | G16: =G15/J15*100 -> 0 | H16: =H15/J15*100 -> 0 | I16: =I15/J15*100 -> 21.052632 | J16: =SUM(D16:I16) -> 100 | K16: STANDBY | L16: = Peralatan standby

Sheet SUMMARY
A1: Unit | B1: No KKS | C1: Description | D1: Standard | E1: Status Kondisi Terakhir
A3: 1 | B3: LJ10PAC10AP001-001 | C3: EQUIPMENT-CIRCULATING WATER PUMP (CWP) 1A | D3: FLIR | E3: =REKOMENDASI!I6 -> Low | H3: Normal (FLIR) | I3: =COUNTIF(E3:F112,"Normal") -> 61 | J3: =I3/I9 -> 0.55963303
A4: 1 | B4: LJ10PAC10AP002-001 | C4: EQUIPMENT-CIRCULATING WATER PUMP (CWP) 1B | D4: FLIR | E4: =REKOMENDASI!I13 -> Normal | H4: Low (FLIR) | I4: =COUNTIF(E3:F112,"Low") -> 15 | J4: =I4/I9 -> 0.13761468
A5: 1 | B5: LJ10LAC10AP001-001 | C5: EQUIPMENT-BOILER FEEDWATER PUMP (BFP) 1A | D5: FLIR | E5: =REKOMENDASI!I20 -> STD BY | H5: Medium (FLIR) | I5: =COUNTIF(E3:F112,"Medium") -> 12 | J5: =I5/I9 -> 0.11009174
A6: 1 | B6: LJ10LAC10AP002-001 | C6: EQUIPMENT-BOILER FEEDWATER PUMP (BFP) 1B | D6: FLIR | E6: =REKOMENDASI!I30 -> Medium | H6: High (FLIR) | I6: =COUNTIF(E3:F112,"High") -> 0 | J6: =I6/I9 -> 0
A7: 1 | B7: LJ10HNC10AN001-001 | C7: EQUIPMENT-INDUCE DRAUGHT FAN (IDF) 1A | D7: FLIR | E7: =REKOMENDASI!I40 -> Normal | H7: Critical (FLIR) | I7: =COUNTIF(E3:F112,"Critical") -> 0 | J7: =I7/I9 -> 0
A8: 1 | B8: LJ10HNC10AN002-001 | C8: EQUIPMENT-INDUCE DRAUGHT FAN (IDF) 1B | D8: FLIR | E8: =REKOMENDASI!I48 -> Low | H8: Standby | I8: =COUNTIF(E3:F112,"STD BY") -> 21 | J8: =I8/I9 -> 0.19266055
A9: 1 | B9: LJ10HLB10AN001-001 | C9: EQUIPMENT-PRIMARY AIR FAN (PAF) 1A | D9: FLIR | E9: =REKOMENDASI!I56 -> Low | H9: Unit 1 | I9: =SUM(I3:I8) -> 109
A10: 1 | B10: LJ10HLB10AN002-001 | C10: EQUIPMENT-PRIMARY AIR FAN (PAF) 1B | D10: FLIR | E10: =REKOMENDASI!I64 -> Low | H10: Normal (FLIR) | I10: =COUNTIF(E3:F32,"Normal") -> 14
A11: 1 | B11: LJ10HLB10AN003-001 | C11: EQUIPMENT-SECONDARY AIR FAN (SAF) 1A | D11: FLIR | E11: =REKOMENDASI!I72 -> Normal | H11: Low (FLIR) | I11: =COUNTIF(E3:F32,"Low") -> 7
A12: 1 | B12: LJ10HLB10AN004-001 | C12: EQUIPMENT-SECONDARY AIR FAN (SAF) 1B | D12: FLIR | E12: =REKOMENDASI!I80 -> Low | H12: Medium (FLIR) | I12: =COUNTIF(E3:F32,"Medium") -> 5
A13: 1 | B13: LJ10LCB10AP010-001 | C13: EQUIPMENT-CONDENSATE EXTRACTION PUMP (CEP) 1A | D13: FLIR | E13: =REKOMENDASI!I88 -> STD BY | H13: High (FLIR) | I13: =COUNTIF(E3:F32,"High") -> 0
A14: 1 | B14: LJ10LCB10AP020-001 | C14: EQUIPMENT-CONDENSATE EXTRACTION PUMP (CEP) 1B | D14: FLIR | E14: =REKOMENDASI!I95 -> Low | H14: Critical (FLIR) | I14: =COUNTIF(E3:F32,"Critical") -> 0
A15: 1 | B15: LJ10PGB10AP001-001 | C15: EQUIPMENT-CLOSED COOLING CIRCULATING WATER PUMP (C3WP) 1A | D15: FLIR | E15: =REKOMENDASI!I102 -> Medium | H15: Standby | I15: =COUNTIF(E3:F32,"STD BY") -> 4
A16: 1 | B16: LJ10PGB10AP002-001 | C16: EQUIPMENT-CLOSED COOLING CIRCULATING WATER PUMP (C3WP) 1B | D16: FLIR | E16: =REKOMENDASI!I109 -> Medium | H16: Unit 2
A17: 1 | B17: LJ10MAG10AP011-001 | C17: EQUIPMENT-VACUUM PUMP 1A | D17: FLIR | E17: =REKOMENDASI!I116 -> Medium | H17: Normal (FLIR) | I17: =COUNTIF(E33:F56,"Normal") -> 14
A18: 1 | B18: LJ10MAG10AP012-001 | C18: EQUIPMENT-VACUUM PUMP 1B | D18: FLIR | E18: =REKOMENDASI!I124 -> Low | H18: Low (FLIR) | I18: =COUNTIF(E33:F56,"Low") -> 4
A19: 1 | B19: LJ10GCK10AP005-001 | C19: EQUIPMENT-BWRO PUMP 1A | D19: FLIR | E19: =REKOMENDASI!I132 -> Normal | H19: Medium (FLIR) | I19: =COUNTIF(E33:F56,"Medium") -> 1
A20: 1 | B20: LJ10GCK10AP006-001 | C20: EQUIPMENT-BWRO PUMP 1B | D20: FLIR | E20: =REKOMENDASI!I135 -> STD BY | H20: High (FLIR) | I20: =COUNTIF(E33:F56,"High") -> 0
A21: 1 | B21: LJ10GCK10AP007-001 | C21: EQUIPMENT-HIGH PRESSURE SWRO PUMP 1A | D21: FLIR | E21: =REKOMENDASI!I138 -> STD BY | H21: Critical (FLIR) | I21: =COUNTIF(E33:F56,"Critical") -> 0
A22: 1 | B22: LJ10GCK10AP008-001 | C22: EQUIPMENT-HIGH PRESSURE SWRO PUMP 1B | D22: FLIR | E22: =REKOMENDASI!I141 -> Normal | H22: Standby | I22: =COUNTIF(E33:F56,"STD BY") -> 5
A23: 1 | B23: LJ10MAA10HB010-001 | C23: EQUIPMENT-HP TURBINE ASSEMBLY UNIT 1 | D23: FLIR | E23: =REKOMENDASI!I144 -> Normal | H23: Unit 3
A24: 1 | B24: LJ10MKA10AG001-001 | C24: EQUIPMENT-GENERATOR UNIT 1 | D24: FLIR | E24: =REKOMENDASI!I146 -> Normal | H24: Normal (FLIR) | I24: =COUNTIF(E57:F94,"Normal") -> 17
A25: 1 | B25: LJ10BFT10GT001-001 | C25: EQUIPMENT-LV TRANSFORMER 43T UNIT 1 | D25: FLIR | E25: =REKOMENDASI!I149 -> Normal | H25: Low (FLIR) | I25: =COUNTIF(E57:F94,"Low") -> 4
A26: 1 | B26: LJ10BFT10GT002-001 | C26: EQUIPMENT-LV TRANSFORMER 44T UNIT 1 | D26: FLIR | E26: =REKOMENDASI!I157 -> Normal | H26: Medium (FLIR) | I26: =COUNTIF(E57:F94,"Medium") -> 5
A27: 1 | B27: LJ10BFT10GT007-001 | C27: EQUIPMENT- LV TRANSFORMER EXCITATION | D27: FLIR | E27: =REKOMENDASI!I165 -> Normal | H27: High (FLIR) | I27: =COUNTIF(E57:F94,"High") -> 0
A28: 1 | B28: LJ10MAV10AP001-001 | C28: EQUIPMENT-AC LUBE OIL PUMP UNIT 1 | D28: FLIR | E28: =REKOMENDASI!I173 -> Medium | H28: Critical (FLIR) | I28: =COUNTIF(E57:F94,"Critical") -> 0
A29: 1 | B29: LJ10MAV10AP003-001 | C29: EQUIPMENT-DC LUBE OIL PUMP UNIT 1 | D29: FLIR | E29: =REKOMENDASI!I178 -> Normal | H29: Standby | I29: =COUNTIF(E57:F94,"STD BY") -> 11
A30: 1 | B30: LJ10BAT10GT001-001 | C30: EQUIPMENT-GENERATOR TRANSFORMER (GT) 34.5 MVA 150/6.3 KV UNIT 1 | D30: FLIR | E30: =REKOMENDASI!I183 -> Normal | H30: Common
A31: 1 | B31: LJ10BBT10GT002-001 | C31: EQUIPMENT-TRANSFORMER ASH HANDLING 1 | D31: FLIR | E31: =REKOMENDASI!I193 -> Normal | H31: Normal (FLIR) | I31: =COUNTIF(E95:F112,"Normal") -> 16
A32: 1 | B32: LJ10BBT10GT003-001 | C32: EQUIPMENT-TRANSFORMER ASH HANDLING 2 | D32: FLIR | E32: =REKOMENDASI!I204 -> Normal | H32: Low (FLIR) | I32: =COUNTIF(E95:F112,"Low") -> 0
A33: 2 | B33: LJ20PAC10AP001-001 | C33: EQUIPMENT-CIRCULATING WATER PUMP (CWP) 2A | D33: FLIR | E33: =REKOMENDASI!I215 -> STD BY | H33: Medium (FLIR) | I33: =COUNTIF(E95:F112,"Medium") -> 1
A34: 2 | B34: LJ20PAC10AP002-001 | C34: EQUIPMENT-CIRCULATING WATER PUMP (CWP) 2B | D34: FLIR | E34: =REKOMENDASI!I222 -> Normal | H34: High (FLIR) | I34: =COUNTIF(E95:F112,"High") -> 0
A35: 2 | B35: LJ20LAC10AP001-001 | C35: EQUIPMENT-BOILER FEEDWATER PUMP (BFP) 2A | D35: FLIR | E35: =REKOMENDASI!I229 -> STD BY | H35: Critical (FLIR) | I35: =COUNTIF(E95:F112,"Critical") -> 0
A36: 2 | B36: LJ20LAC10AP002-001 | C36: EQUIPMENT-BOILER FEEDWATER PUMP (BFP) 2B | D36: FLIR | E36: =REKOMENDASI!I239 -> Low | H36: Standby | I36: =COUNTIF(E95:F112,"STD BY") -> 1
A37: 2 | B37: LJ20HNC10AN001-001 | C37: EQUIPMENT-INDUCE DRAUGHT FAN (IDF) 2A | D37: FLIR | E37: =REKOMENDASI!I249 -> Normal
A38: 2 | B38: LJ20HNC10AN002-001 | C38: EQUIPMENT-INDUCE DRAUGHT FAN (IDF) 2B | D38: FLIR | E38: =REKOMENDASI!I257 -> Normal
A39: 2 | B39: LJ20HLB10AN001-001 | C39: EQUIPMENT-PRIMARY AIR FAN (PAF) 2A | D39: FLIR | E39: =REKOMENDASI!I265 -> Low
A40: 2 | B40: LJ20HLB10AN002-001 | C40: EQUIPMENT-PRIMARY AIR FAN (PAF) 2B | D40: FLIR | E40: =REKOMENDASI!I273 -> Low
A41: 2 | B41: LJ20HLB10AN003-001 | C41: EQUIPMENT-SECONDARY AIR FAN (SAF) 2A | D41: FLIR | E41: =REKOMENDASI!I281 -> Low
...

Sheet REKOMENDASI
A1: EXECUTIVE SUMMARY IR THERMOGRAPHY JULI 2026
A3: Unit | B3: No. KKS | C3: Description | D3: Measurement Point | E3: Upper Warning Limit Maximo | F3: Upper Action Limit Maximo | G3: Analysis Standard | H3: Status per Point Measurement | I3: Overall Status Equipment | J3: T rise | K3: T max Reference | L3: Data Analysis | N3: Keterangan
L5: Date | M5: ( °C )
A6: 1 | B6: LJ10PAC10AP001-001 | C6: EQUIPMENT-CIRCULATING WATER PUMP (CWP) 1A | D6: Cover winding motor | E6: =(K6+11) -> 71 | F6: =(E6+10) -> 81 | G6: FLIR | H6: =IF(J6="",("-"),(IF(J6="STD BY",("STD BY"),(IF(J6="N/A",("N/A"),(IF(J6<5,("Normal"),(IF(J6<11,("Low"),(IF(J6<21,("Medium"),(IF(J6<41,("High"),("Critical")))))))))))))) -> Normal | I6: =IF(COUNTIF(H6:H12,"-")>0,("-"),(IF(COUNTIF(H6:H12,"STD BY")>0,("STD BY"),(IF(COUNTIF(H6:H12,"N/A")>0,("N/A"),(IF(COUNTIF(H6:H12,"Critical")>0,("Critical"),(IF(COUNTIF(H6:H12,"High")>0,("High"),(IF(COUNTIF(H6:H12,"Medium")>0,("Medium"),(IF(COUNTIF(H6:H12,"Low")>0,("Low"),("Normal")))))))))))))) -> Low | J6: =IF(M6="",(""),(IF(M6="STD BY",("STD BY"),(IF(M6="N/A",("N/A"),(IF(M6-K6>0,(M6-K6),(0)))))))) -> 0 | K6: 60 | L6: 46217 | M6: 56 | N6: Keterangan : Tidak ada hotspot / kenaikan temperature yang berbahaya. Rekomendasi : Lakukan pengukuran thermography sesuai 52 week.
D7: Bearing 1 motor | E7: =(K7+11) -> 61 | F7: =(E7+10) -> 71 | G7: FLIR | H7: =IF(J7="",("-"),(IF(J7="STD BY",("STD BY"),(IF(J7="N/A",("N/A"),(IF(J7<5,("Normal"),(IF(J7<11,("Low"),(IF(J7<21,("Medium"),(IF(J7<41,("High"),("Critical")))))))))))))) -> Normal | J7: =IF(M7="",(""),(IF(M7="STD BY",("STD BY"),(IF(M7="N/A",("N/A"),(IF(M7-K7>0,(M7-K7),(0)))))))) -> 0 | K7: 50 | L7: 46217 | M7: 44.7
D8: Bearing 2 motor | E8: =(K8+11) -> 61 | F8: =(E8+10) -> 71 | G8: FLIR | H8: =IF(J8="",("-"),(IF(J8="STD BY",("STD BY"),(IF(J8="N/A",("N/A"),(IF(J8<5,("Normal"),(IF(J8<11,("Low"),(IF(J8<21,("Medium"),(IF(J8<41,("High"),("Critical")))))))))))))) -> Normal | J8: =IF(M8="",(""),(IF(M8="STD BY",("STD BY"),(IF(M8="N/A",("N/A"),(IF(M8-K8>0,(M8-K8),(0)))))))) -> 0 | K8: 50 | L8: 46217 | M8: 46.1
D9: Bearing 3 pump | E9: =(K9+11) -> 61 | F9: =(E9+10) -> 71 | G9: FLIR | H9: =IF(J9="",("-"),(IF(J9="STD BY",("STD BY"),(IF(J9="N/A",("N/A"),(IF(J9<5,("Normal"),(IF(J9<11,("Low"),(IF(J9<21,("Medium"),(IF(J9<41,("High"),("Critical")))))))))))))) -> Low | J9: =IF(M9="",(""),(IF(M9="STD BY",("STD BY"),(IF(M9="N/A",("N/A"),(IF(M9-K9>0,(M9-K9),(0)))))))) -> 5.4 | K9: 50 | L9: 46217 | M9: 55.4
D10: Conection Phasa R | E10: =(K10+11) -> 41 | F10: =(E10+10) -> 51 | G10: FLIR | H10: =IF(J10="",("-"),(IF(J10="STD BY",("STD BY"),(IF(J10="N/A",("N/A"),(IF(J10<5,("Normal"),(IF(J10<11,("Low"),(IF(J10<21,("Medium"),(IF(J10<41,("High"),("Critical")))))))))))))) -> Normal | J10: =IF(M10="",(""),(IF(M10="STD BY",("STD BY"),(IF(M10="N/A",("N/A"),(IF(M10-K10>0,(M10-K10),(0)))))))) -> 2.5 | K10: 30 | L10: 46217 | M10: 32.5
D11: Conection Phasa S | E11: =(K11+11) -> 41 | F11: =(E11+10) -> 51 | G11: FLIR | H11: =IF(J11="",("-"),(IF(J11="STD BY",("STD BY"),(IF(J11="N/A",("N/A"),(IF(J11<5,("Normal"),(IF(J11<11,("Low"),(IF(J11<21,("Medium"),(IF(J11<41,("High"),("Critical")))))))))))))) -> Normal | J11: =IF(M11="",(""),(IF(M11="STD BY",("STD BY"),(IF(M11="N/A",("N/A"),(IF(M11-K11>0,(M11-K11),(0)))))))) -> 2.2 | K11: 30 | L11: 46217 | M11: 32.2
D12: Conection Phasa T | E12: =(K12+11) -> 41 | F12: =(E12+10) -> 51 | G12: FLIR | H12: =IF(J12="",("-"),(IF(J12="STD BY",("STD BY"),(IF(J12="N/A",("N/A"),(IF(J12<5,("Normal"),(IF(J12<11,("Low"),(IF(J12<21,("Medium"),(IF(J12<41,("High"),("Critical")))))))))))))) -> Normal | J12: =IF(M12="",(""),(IF(M12="STD BY",("STD BY"),(IF(M12="N/A",("N/A"),(IF(M12-K12>0,(M12-K12),(0)))))))) -> 2.2 | K12: 30 | L12: 46217 | M12: 32.2
A13: 1 | B13: LJ10PAC10AP002-001 | C13: EQUIPMENT-CIRCULATING WATER PUMP (CWP) 1B | D13: Cover winding motor | E13: =(K13+11) -> 71 | F13: =(E13+10) -> 81 | G13: FLIR | H13: =IF(J13="",("-"),(IF(J13="STD BY",("STD BY"),(IF(J13="N/A",("N/A"),(IF(J13<5,("Normal"),(IF(J13<11,("Low"),(IF(J13<21,("Medium"),(IF(J13<41,("High"),("Critical")))))))))))))) -> Normal | I13: =IF(COUNTIF(H13:H19,"-")>0,("-"),(IF(COUNTIF(H13:H19,"STD BY")>0,("STD BY"),(IF(COUNTIF(H13:H19,"N/A")>0,("N/A"),(IF(COUNTIF(H13:H19,"Critical")>0,("Critical"),(IF(COUNTIF(H13:H19,"High")>0,("High"),(IF(COUNTIF(H13:H19,"Medium")>0,("Medium"),(IF(COUNTIF(H13:H19,"Low")>0,("Low"),("Normal")))))))))))))) -> Normal | J13: =IF(M13="",(""),(IF(M13="STD BY",("STD BY"),(IF(M13="N/A",("N/A"),(IF(M13-K13>0,(M13-K13),(0)))))))) -> 0 | K13: 60 | L13: 46226 | M13: 52.7 | N13: Keterangan : Tidak ada hotspot / kenaikan temperature yang berbahaya. Rekomendasi : Lakukan pengukuran thermography sesuai 52 week.
D14: Bearing 1 motor | E14: =(K14+11) -> 61 | F14: =(E14+10) -> 71 | G14: FLIR | H14: =IF(J14="",("-"),(IF(J14="STD BY",("STD BY"),(IF(J14="N/A",("N/A"),(IF(J14<5,("Normal"),(IF(J14<11,("Low"),(IF(J14<21,("Medium"),(IF(J14<41,("High"),("Critical")))))))))))))) -> Normal | J14: =IF(M14="",(""),(IF(M14="STD BY",("STD BY"),(IF(M14="N/A",("N/A"),(IF(M14-K14>0,(M14-K14),(0)))))))) -> 0 | K14: 50 | L14: 46226 | M14: 47.6
D15: Bearing 2 motor | E15: =(K15+11) -> 61 | F15: =(E15+10) -> 71 | G15: FLIR | H15: =IF(J15="",("-"),(IF(J15="STD BY",("STD BY"),(IF(J15="N/A",("N/A"),(IF(J15<5,("Normal"),(IF(J15<11,("Low"),(IF(J15<21,("Medium"),(IF(J15<41,("High"),("Critical")))))))))))))) -> Normal | J15: =IF(M15="",(""),(IF(M15="STD BY",("STD BY"),(IF(M15="N/A",("N/A"),(IF(M15-K15>0,(M15-K15),(0)))))))) -> 0 | K15: 50 | L15: 46226 | M15: 49.3
D16: Bearing 3 pump | E16: =(K16+11) -> 61 | F16: =(E16+10) -> 71 | G16: FLIR | H16: =IF(J16="",("-"),(IF(J16="STD BY",("STD BY"),(IF(J16="N/A",("N/A"),(IF(J16<5,("Normal"),(IF(J16<11,("Low"),(IF(J16<21,("Medium"),(IF(J16<41,("High"),("Critical")))))))))))))) -> Normal | J16: =IF(M16="",(""),(IF(M16="STD BY",("STD BY"),(IF(M16="N/A",("N/A"),(IF(M16-K16>0,(M16-K16),(0)))))))) -> 0 | K16: 50 | L16: 46226 | M16: 50
D17: Conection Phasa R | E17: =(K17+11) -> 41 | F17: =(E17+10) -> 51 | G17: FLIR | H17: =IF(J17="",("-"),(IF(J17="STD BY",("STD BY"),(IF(J17="N/A",("N/A"),(IF(J17<5,("Normal"),(IF(J17<11,("Low"),(IF(J17<21,("Medium"),(IF(J17<41,("High"),("Critical")))))))))))))) -> Normal | J17: =IF(M17="",(""),(IF(M17="STD BY",("STD BY"),(IF(M17="N/A",("N/A"),(IF(M17-K17>0,(M17-K17),(0)))))))) -> 3.6 | K17: 30 | L17: 46226 | M17: 33.6
D18: Conection Phasa S | E18: =(K18+11) -> 41 | F18: =(E18+10) -> 51 | G18: FLIR | H18: =IF(J18="",("-"),(IF(J18="STD BY",("STD BY"),(IF(J18="N/A",("N/A"),(IF(J18<5,("Normal"),(IF(J18<11,("Low"),(IF(J18<21,("Medium"),(IF(J18<41,("High"),("Critical")))))))))))))) -> Normal | J18: =IF(M18="",(""),(IF(M18="STD BY",("STD BY"),(IF(M18="N/A",("N/A"),(IF(M18-K18>0,(M18-K18),(0)))))))) -> 3.5 | K18: 30 | L18: 46226 | M18: 33.5
D19: Conection Phasa T | E19: =(K19+11) -> 41 | F19: =(E19+10) -> 51 | G19: FLIR | H19: =IF(J19="",("-"),(IF(J19="STD BY",("STD BY"),(IF(J19="N/A",("N/A"),(IF(J19<5,("Normal"),(IF(J19<11,("Low"),(IF(J19<21,("Medium"),(IF(J19<41,("High"),("Critical")))))))))))))) -> Normal | J19: =IF(M19="",(""),(IF(M19="STD BY",("STD BY"),(IF(M19="N/A",("N/A"),(IF(M19-K19>0,(M19-K19),(0)))))))) -> 3.3 | K19: 30 | L19: 46226 | M19: 33.3
A20: 1 | B20: LJ10LAC10AP001-001 | C20: EQUIPMENT-BOILER FEEDWATER PUMP (BFP) 1A | D20: Cover winding motor | E20: =(K20+11) -> 71 | F20: =(E20+10) -> 81 | G20: FLIR | H20: =IF(J20="",("-"),(IF(J20="STD BY",("STD BY"),(IF(J20="N/A",("N/A"),(IF(J20<5,("Normal"),(IF(J20<11,("Low"),(IF(J20<21,("Medium"),(IF(J20<41,("High"),("Critical")))))))))))))) -> STD BY | I20: =IF(COUNTIF(H20:H29,"-")>0,("-"),(IF(COUNTIF(H20:H29,"STD BY")>0,("STD BY"),(IF(COUNTIF(H20:H29,"N/A")>0,("N/A"),(IF(COUNTIF(H20:H29,"Critical")>0,("Critical"),(IF(COUNTIF(H20:H29,"High")>0,("High"),(IF(COUNTIF(H20:H29,"Medium")>0,("Medium"),(IF(COUNTIF(H20:H29,"Low")>0,("Low"),("Normal")))))))))))))) -> STD BY | J20: =IF(M20="",(""),(IF(M20="STD BY",("STD BY"),(IF(M20="N/A",("N/A"),(IF(M20-K20>0,(M20-K20),(0)))))))) -> STD BY | K20: 60 | M20: STD BY | N20: Equipment dalam keadaan standby saat rutin PDM dilakukan.
D21: Bearing 1 motor | E21: =(K21+11) -> 66 | F21: =(E21+10) -> 76 | G21: FLIR | H21: =IF(J21="",("-"),(IF(J21="STD BY",("STD BY"),(IF(J21="N/A",("N/A"),(IF(J21<5,("Normal"),(IF(J21<11,("Low"),(IF(J21<21,("Medium"),(IF(J21<41,("High"),("Critical")))))))))))))) -> STD BY | J21: =IF(M21="",(""),(IF(M21="STD BY",("STD BY"),(IF(M21="N/A",("N/A"),(IF(M21-K21>0,(M21-K21),(0)))))))) -> STD BY | K21: 55 | M21: STD BY
D22: Bearing 2 motor | E22: =(K22+11) -> 61 | F22: =(E22+10) -> 71 | G22: FLIR | H22: =IF(J22="",("-"),(IF(J22="STD BY",("STD BY"),(IF(J22="N/A",("N/A"),(IF(J22<5,("Normal"),(IF(J22<11,("Low"),(IF(J22<21,("Medium"),(IF(J22<41,("High"),("Critical")))))))))))))) -> STD BY | J22: =IF(M22="",(""),(IF(M22="STD BY",("STD BY"),(IF(M22="N/A",("N/A"),(IF(M22-K22>0,(M22-K22),(0)))))))) -> STD BY | K22: 50 | M22: STD BY
D23: Bearing 3 Fluid Coupling | E23: =(K23+11) -> 61 | F23: =(E23+10) -> 71 | G23: FLIR | H23: =IF(J23="",("-"),(IF(J23="STD BY",("STD BY"),(IF(J23="N/A",("N/A"),(IF(J23<5,("Normal"),(IF(J23<11,("Low"),(IF(J23<21,("Medium"),(IF(J23<41,("High"),("Critical")))))))))))))) -> STD BY | J23: =IF(M23="",(""),(IF(M23="STD BY",("STD BY"),(IF(M23="N/A",("N/A"),(IF(M23-K23>0,(M23-K23),(0)))))))) -> STD BY | K23: 50 | M23: STD BY
D24: Bearing 4 Fluid Coupling | E24: =(K24+11) -> 61 | F24: =(E24+10) -> 71 | G24: FLIR | H24: =IF(J24="",("-"),(IF(J24="STD BY",("STD BY"),(IF(J24="N/A",("N/A"),(IF(J24<5,("Normal"),(IF(J24<11,("Low"),(IF(J24<21,("Medium"),(IF(J24<41,("High"),("Critical")))))))))))))) -> STD BY | J24: =IF(M24="",(""),(IF(M24="STD BY",("STD BY"),(IF(M24="N/A",("N/A"),(IF(M24-K24>0,(M24-K24),(0)))))))) -> STD BY | K24: 50 | M24: STD BY
D25: Bearing 5 pump | E25: =(K25+11) -> 61 | F25: =(E25+10) -> 71 | G25: FLIR | H25: =IF(J25="",("-"),(IF(J25="STD BY",("STD BY"),(IF(J25="N/A",("N/A"),(IF(J25<5,("Normal"),(IF(J25<11,("Low"),(IF(J25<21,("Medium"),(IF(J25<41,("High"),("Critical")))))))))))))) -> STD BY | J25: =IF(M25="",(""),(IF(M25="STD BY",("STD BY"),(IF(M25="N/A",("N/A"),(IF(M25-K25>0,(M25-K25),(0)))))))) -> STD BY | K25: 50 | M25: STD BY
D26: Bearing 6 pump | E26: =(K26+11) -> 61 | F26: =(E26+10) -> 71 | G26: FLIR | H26: =IF(J26="",("-"),(IF(J26="STD BY",("STD BY"),(IF(J26="N/A",("N/A"),(IF(J26<5,("Normal"),(IF(J26<11,("Low"),(IF(J26<21,("Medium"),(IF(J26<41,("High"),("Critical")))))))))))))) -> STD BY | J26: =IF(M26="",(""),(IF(M26="STD BY",("STD BY"),(IF(M26="N/A",("N/A"),(IF(M26-K26>0,(M26-K26),(0)))))))) -> STD BY | K26: 50 | M26: STD BY
D27: Conection Phasa R | E27: =(K27+11) -> 41 | F27: =(E27+10) -> 51 | G27: FLIR | H27: =IF(J27="",("-"),(IF(J27="STD BY",("STD BY"),(IF(J27="N/A",("N/A"),(IF(J27<5,("Normal"),(IF(J27<11,("Low"),(IF(J27<21,("Medium"),(IF(J27<41,("High"),("Critical")))))))))))))) -> STD BY | J27: =IF(M27="",(""),(IF(M27="STD BY",("STD BY"),(IF(M27="N/A",("N/A"),(IF(M27-K27>0,(M27-K27),(0)))))))) -> STD BY | K27: 30 | M27: STD BY
D28: Conection Phasa S | E28: =(K28+11) -> 41 | F28: =(E28+10) -> 51 | G28: FLIR | H28: =IF(J28="",("-"),(IF(J28="STD BY",("STD BY"),(IF(J28="N/A",("N/A"),(IF(J28<5,("Normal"),(IF(J28<11,("Low"),(IF(J28<21,("Medium"),(IF(J28<41,("High"),("Critical")))))))))))))) -> STD BY | J28: =IF(M28="",(""),(IF(M28="STD BY",("STD BY"),(IF(M28="N/A",("N/A"),(IF(M28-K28>0,(M28-K28),(0)))))))) -> STD BY | K28: 30 | M28: STD BY
D29: Conection Phasa T | E29: =(K29+11) -> 41 | F29: =(E29+10) -> 51 | G29: FLIR | H29: =IF(J29="",("-"),(IF(J29="STD BY",("STD BY"),(IF(J29="N/A",("N/A"),(IF(J29<5,("Normal"),(IF(J29<11,("Low"),(IF(J29<21,("Medium"),(IF(J29<41,("High"),("Critical")))))))))))))) -> STD BY | J29: =IF(M29="",(""),(IF(M29="STD BY",("STD BY"),(IF(M29="N/A",("N/A"),(IF(M29-K29>0,(M29-K29),(0)))))))) -> STD BY | K29: 30 | M29: STD BY
A30: 1 | B30: LJ10LAC10AP002-001 | C30: EQUIPMENT-BOILER FEEDWATER PUMP (BFP) 1B | D30: Cover winding motor | E30: =(K30+11) -> 71 | F30: =(E30+10) -> 81 | G30: FLIR | H30: =IF(J30="",("-"),(IF(J30="STD BY",("STD BY"),(IF(J30="N/A",("N/A"),(IF(J30<5,("Normal"),(IF(J30<11,("Low"),(IF(J30<21,("Medium"),(IF(J30<41,("High"),("Critical")))))))))))))) -> Low | I30: =IF(COUNTIF(H30:H39,"-")>0,("-"),(IF(COUNTIF(H30:H39,"STD BY")>0,("STD BY"),(IF(COUNTIF(H30:H39,"N/A")>0,("N/A"),(IF(COUNTIF(H30:H39,"Critical")>0,("Critical"),(IF(COUNTIF(H30:H39,"High")>0,("High"),(IF(COUNTIF(H30:H39,"Medium")>0,("Medium"),(IF(COUNTIF(H30:H39,"Low")>0,("Low"),("Normal")))))))))))))) -> Medium | J30: =IF(M30="",(""),(IF(M30="STD BY",("STD BY"),(IF(M30="N/A",("N/A"),(IF(M30-K30>0,(M30-K30),(0)))))))) -> 8.7 | K30: 60 | L30: 46223 | M30: 68.7 | N30: Keterangan : Tidak ada hotspot / kenaikan temperature yang berbahaya. Rekomendasi : Lakukan pengukuran thermography sesuai 52 week.
D31: Bearing 1 motor | E31: =(K31+11) -> 66 | F31: =(E31+10) -> 76 | G31: FLIR | H31: =IF(J31="",("-"),(IF(J31="STD BY",("STD BY"),(IF(J31="N/A",("N/A"),(IF(J31<5,("Normal"),(IF(J31<11,("Low"),(IF(J31<21,("Medium"),(IF(J31<41,("High"),("Critical")))))))))))))) -> Normal | J31: =IF(M31="",(""),(IF(M31="STD BY",("STD BY"),(IF(M31="N/A",("N/A"),(IF(M31-K31>0,(M31-K31),(0)))))))) -> 3.5 | K31: 55 | L31: 46223 | M31: 58.5
D32: Bearing 2 motor | E32: =(K32+11) -> 61 | F32: =(E32+10) -> 71 | G32: FLIR | H32: =IF(J32="",("-"),(IF(J32="STD BY",("STD BY"),(IF(J32="N/A",("N/A"),(IF(J32<5,("Normal"),(IF(J32<11,("Low"),(IF(J32<21,("Medium"),(IF(J32<41,("High"),("Critical")))))))))))))) -> Normal | J32: =IF(M32="",(""),(IF(M32="STD BY",("STD BY"),(IF(M32="N/A",("N/A"),(IF(M32-K32>0,(M32-K32),(0)))))))) -> 0.3 | K32: 50 | L32: 46223 | M32: 50.3
D33: Bearing 3 Fluid Coupling | E33: =(K33+11) -> 61 | F33: =(E33+10) -> 71 | G33: FLIR | H33: =IF(J33="",("-"),(IF(J33="STD BY",("STD BY"),(IF(J33="N/A",("N/A"),(IF(J33<5,("Normal"),(IF(J33<11,("Low"),(IF(J33<21,("Medium"),(IF(J33<41,("High"),("Critical")))))))))))))) -> Normal | J33: =IF(M33="",(""),(IF(M33="STD BY",("STD BY"),(IF(M33="N/A",("N/A"),(IF(M33-K33>0,(M33-K33),(0)))))))) -> 1.1 | K33: 50 | L33: 46223 | M33: 51.1
D34: Bearing 4 Fluid Coupling | E34: =(K34+11) -> 61 | F34: =(E34+10) -> 71 | G34: FLIR | H34: =IF(J34="",("-"),(IF(J34="STD BY",("STD BY"),(IF(J34="N/A",("N/A"),(IF(J34<5,("Normal"),(IF(J34<11,("Low"),(IF(J34<21,("Medium"),(IF(J34<41,("High"),("Critical")))))))))))))) -> Normal | J34: =IF(M34="",(""),(IF(M34="STD BY",("STD BY"),(IF(M34="N/A",("N/A"),(IF(M34-K34>0,(M34-K34),(0)))))))) -> 0.1 | K34: 50 | L34: 46223 | M34: 50.1
D35: Bearing 5 pump | E35: =(K35+11) -> 61 | F35: =(E35+10) -> 71 | G35: FLIR | H35: =IF(J35="",("-"),(IF(J35="STD BY",("STD BY"),(IF(J35="N/A",("N/A"),(IF(J35<5,("Normal"),(IF(J35<11,("Low"),(IF(J35<21,("Medium"),(IF(J35<41,("High"),("Critical")))))))))))))) -> Normal | J35: =IF(M35="",(""),(IF(M35="STD BY",("STD BY"),(IF(M35="N/A",("N/A"),(IF(M35-K35>0,(M35-K35),(0)))))))) -> 0.6 | K35: 50 | L35: 46223 | M35: 50.6
D36: Bearing 6 pump | E36: =(K36+11) -> 61 | F36: =(E36+10) -> 71 | G36: FLIR | H36: =IF(J36="",("-"),(IF(J36="STD BY",("STD BY"),(IF(J36="N/A",("N/A"),(IF(J36<5,("Normal"),(IF(J36<11,("Low"),(IF(J36<21,("Medium"),(IF(J36<41,("High"),("Critical")))))))))))))) -> Medium | J36: =IF(M36="",(""),(IF(M36="STD BY",("STD BY"),(IF(M36="N/A",("N/A"),(IF(M36-K36>0,(M36-K36),(0)))))))) -> 17.1 | K36: 50 | L36: 46223 | M36: 67.1
D37: Conection Phasa R | E37: =(K37+11) -> 41 | F37: =(E37+10) -> 51 | G37: FLIR | H37: =IF(J37="",("-"),(IF(J37="STD BY",("STD BY"),(IF(J37="N/A",("N/A"),(IF(J37<5,("Normal"),(IF(J37<11,("Low"),(IF(J37<21,("Medium"),(IF(J37<41,("High"),("Critical")))))))))))))) -> Normal | J37: =IF(M37="",(""),(IF(M37="STD BY",("STD BY"),(IF(M37="N/A",("N/A"),(IF(M37-K37>0,(M37-K37),(0)))))))) -> 0.9 | K37: 30 | L37: 46223 | M37: 30.9
D38: Conection Phasa S | E38: =(K38+11) -> 41 | F38: =(E38+10) -> 51 | G38: FLIR | H38: =IF(J38="",("-"),(IF(J38="STD BY",("STD BY"),(IF(J38="N/A",("N/A"),(IF(J38<5,("Normal"),(IF(J38<11,("Low"),(IF(J38<21,("Medium"),(IF(J38<41,("High"),("Critical")))))))))))))) -> Normal | J38: =IF(M38="",(""),(IF(M38="STD BY",("STD BY"),(IF(M38="N/A",("N/A"),(IF(M38-K38>0,(M38-K38),(0)))))))) -> 0.9 | K38: 30 | L38: 46223 | M38: 30.9
D39: Conection Phasa T | E39: =(K39+11) -> 41 | F39: =(E39+10) -> 51 | G39: FLIR | H39: =IF(J39="",("-"),(IF(J39="STD BY",("STD BY"),(IF(J39="N/A",("N/A"),(IF(J39<5,("Normal"),(IF(J39<11,("Low"),(IF(J39<21,("Medium"),(IF(J39<41,("High"),("Critical")))))))))))))) -> Normal | J39: =IF(M39="",(""),(IF(M39="STD BY",("STD BY"),(IF(M39="N/A",("N/A"),(IF(M39-K39>0,(M39-K39),(0)))))))) -> 0.9 | K39: 30 | L39: 46223 | M39: 30.9
A40: 1 | B40: LJ10HNC10AN001-001 | C40: EQUIPMENT-INDUCE DRAUGHT FAN (IDF) 1A | D40: Cover winding motor | E40: =(K40+11) -> 71 | F40: =(E40+10) -> 81 | G40: FLIR | H40: =IF(J40="",("-"),(IF(J40="STD BY",("STD BY"),(IF(J40="N/A",("N/A"),(IF(J40<5,("Normal"),(IF(J40<11,("Low"),(IF(J40<21,("Medium"),(IF(J40<41,("High"),("Critical")))))))))))))) -> Normal | I40: =IF(COUNTIF(H40:H47,"-")>0,("-"),(IF(COUNTIF(H40:H47,"STD BY")>0,("STD BY"),(IF(COUNTIF(H40:H47,"N/A")>0,("N/A"),(IF(COUNTIF(H40:H47,"Critical")>0,("Critical"),(IF(COUNTIF(H40:H47,"High")>0,("High"),(IF(COUNTIF(H40:H47,"Medium")>0,("Medium"),(IF(COUNTIF(H40:H47,"Low")>0,("Low"),("Normal")))))))))))))) -> Normal | J40: =IF(M40="",(""),(IF(M40="STD BY",("STD BY"),(IF(M40="N/A",("N/A"),(IF(M40-K40>0,(M40-K40),(0)))))))) -> 0.9 | K40: 60 | L40: 46216 | M40: 60.9 | N40: Keterangan : Tidak ada hotspot / kenaikan temperature yang berbahaya. Rekomendasi : Lakukan pengukuran thermography sesuai 52 week.
D41: Bearing 1 motor | E41: =(K41+11) -> 61 | F41: =(E41+10) -> 71 | G41: FLIR | H41: =IF(J41="",("-"),(IF(J41="STD BY",("STD BY"),(IF(J41="N/A",("N/A"),(IF(J41<5,("Normal"),(IF(J41<11,("Low"),(IF(J41<21,("Medium"),(IF(J41<41,("High"),("Critical")))))))))))))) -> Normal | J41: =IF(M41="",(""),(IF(M41="STD BY",("STD BY"),(IF(M41="N/A",("N/A"),(IF(M41-K41>0,(M41-K41),(0)))))))) -> 0 | K41: 50 | L41: 46216 | M41: 35.5
D42: Bearing 2 motor | E42: =(K42+11) -> 61 | F42: =(E42+10) -> 71 | G42: FLIR | H42: =IF(J42="",("-"),(IF(J42="STD BY",("STD BY"),(IF(J42="N/A",("N/A"),(IF(J42<5,("Normal"),(IF(J42<11,("Low"),(IF(J42<21,("Medium"),(IF(J42<41,("High"),("Critical")))))))))))))) -> Normal | J42: =IF(M42="",(""),(IF(M42="STD BY",("STD BY"),(IF(M42="N/A",("N/A"),(IF(M42-K42>0,(M42-K42),(0)))))))) -> 2.7 | K42: 50 | L42: 46216 | M42: 52.7
...

Sheet Sheet1
B2: LJ10PAC10AP001-001 | C2: EQUIPMENT-CIRCULATING WATER PUMP (CWP) 1A
B3: LJ10PAC10AP002-001 | C3: EQUIPMENT-CIRCULATING WATER PUMP (CWP) 1B
B4: LJ10LAC10AP001-001 | C4: EQUIPMENT-BOILER FEEDWATER PUMP (BFP) 1A
B5: LJ10LAC10AP002-001 | C5: EQUIPMENT-BOILER FEEDWATER PUMP (BFP) 1B
B6: LJ10HNC10AN001-001 | C6: EQUIPMENT-INDUCE DRAUGHT FAN (IDF) 1A
B7: LJ10HNC10AN002-001 | C7: EQUIPMENT-INDUCE DRAUGHT FAN (IDF) 1B
B8: LJ10HLB10AN001-001 | C8: EQUIPMENT-PRIMARY AIR FAN (PAF) 1A
B9: LJ10HLB10AN002-001 | C9: EQUIPMENT-PRIMARY AIR FAN (PAF) 1B
B10: LJ10HLB10AN003-001 | C10: EQUIPMENT-SECONDARY AIR FAN (SAF) 1A
B11: LJ10HLB10AN004-001 | C11: EQUIPMENT-SECONDARY AIR FAN (SAF) 1B
B12: LJ10LCB10AP010-001 | C12: EQUIPMENT-CONDENSATE EXTRACTION PUMP (CEP) 1A
B13: LJ10LCB10AP020-001 | C13: EQUIPMENT-CONDENSATE EXTRACTION PUMP (CEP) 1B
... B111: LJ00BBA10GT002-001 | C111: EQUIPMENT-TRANSFORMER COAL HANDLING 2
