Workbook

Sheet DASHBOARD
D1: PT. PLN INDONESIA POWER | T1: No. Dok | U1: : FORM.JRG.F.05.001
D2: UNIT BISNIS PEMBANGKITAN JERANJANG | T2: Tgl Terbit | U2: : 1 Sep 2016
D3: BIDANG ENJINERING | T3: Rev | U3: : 00
D4: LAPORAN PDM TEKNOLOGI VIBRASI | T4: Hal | U4: :
A5: HASIL PENGUKURAN PADA EQUIPMENT BULAN JULI 2026
B7: UNIT | D7: LEVEL VIBRASI
D8: LEVEL A | E8: LEVEL B | F8: LEVEL C | G8: LEVEL D | H8: STANDBY | J8: KETERANGAN
B9: UNIT 1 | D9: =COUNTIF(SUMMARY!$X$10:$X$35,"NORMAL") -> 10 | E9: =COUNTIF(SUMMARY!$X$10:$X$35,"PREWARNING") -> 13 | F9: =COUNTIF(SUMMARY!$X$10:$X$35,"WARNING") -> 0 | G9: =COUNTIF(SUMMARY!$X$10:$X$35,"ALARM") -> 1 | H9: =COUNTIF(SUMMARY!$X$10:$X$35,"STAND BY") -> 2 | J9: A | K9: Sangat halus (New machine condition)
B10: UNIT 2 | D10: =COUNTIF(SUMMARY!$X$37:$X$54,"NORMAL") -> 6 | E10: =COUNTIF(SUMMARY!$X$37:$X$54,"PREWARNING") -> 8 | F10: =COUNTIF(SUMMARY!$X$37:$X$54,"WARNING") -> 0 | G10: =COUNTIF(SUMMARY!$X$37:$X$54,"ALARM") -> 0 | H10: =COUNTIF(SUMMARY!$X$37:$X$54,"STAND BY") -> 4 | J10: B | K10: Diperbolehkan beroperasi dalam jangka waktu lama yang tak terbatas (Unlimited long-term operation allowable)
B11: UNIT 3 | D11: =COUNTIF(SUMMARY!$X$58:$X$79,"NORMAL") -> 7 | E11: =COUNTIF(SUMMARY!$X$58:$X$79,"PREWARNING") -> 9 | F11: =COUNTIF(SUMMARY!$X$58:$X$79,"WARNING") -> 0 | G11: =COUNTIF(SUMMARY!$X$58:$X$79,"ALARM") -> 0 | H11: =COUNTIF(SUMMARY!$X$58:$X$79,"STAND BY") -> 6 | J11: C | K11: Diperbolehkan beroperasi dalam jangka waktu singkat (Short-term operation allowable)
B12: COAL HANDLING | D12: =COUNTIF(SUMMARY!$X$90:$X$103,"NORMAL") -> 1 | E12: =COUNTIF(SUMMARY!$X$90:$X$103,"PREWARNING") -> 11 | F12: =COUNTIF(SUMMARY!$X$90:$X$103,"WARNING") -> 1 | G12: =COUNTIF(SUMMARY!$X$90:$X$103,"ALARM") -> 1 | H12: =COUNTIF(SUMMARY!$X$90:$X$103,"STAND BY") -> 0 | J12: D | K12: Bila dioperasikan mengakibatkna kerusakan yang lebih parah (Vibration causes damage) | X12: KETERANGAN
B13: TOTAL | D13: =SUM(D9:D12) -> 24 | E13: =SUM(E9:E12) -> 41 | F13: =SUM(F9:F12) -> 1 | G13: =SUM(G9:G12) -> 2 | H13: =SUM(H9:H12) -> 12 | J13: E | K13: Peralatan Stand BY | X13: A | Y13: Sangat halus (New machine condition)
B14: PERSENTASE (%) | D14: =(D13/SUM(D13:H13)) -> 0.3 | E14: =(E13/SUM(D13:H13)) -> 0.5125 | F14: =(F13/SUM(D13:H13)) -> 0.0125 | G14: =(G13/SUM(D13:H13)) -> 0.025 | H14: =(H13/SUM(D13:H13)) -> 0.15 | X14: B | Y14: Diperbolehkan beroperasi dalam jangka waktu lama yang tak terbatas (Unlimited long-term operation allowable)
X15: C | Y15: Diperbolehkan beroperasi dalam jangka waktu singkat (Short-term operation allowable)
C16: =SUM(#REF!) -> #REF! | X16: D | Y16: Bila dioperasikan mengakibatkna kerusakan yang lebih parah (Vibration causes damage)
X17: E | Y17: Peralatan Stand BY

Sheet SUMMARY
D1: PT. PLN INDONESIA POWER | T1: No. Dok | W1: : FORM.JRG.F.05.001
D2: UNIT BISNIS PEMBANGKITAN JERANJANG | T2: Tgl Terbit | W2: : 1 Sep 2016
D3: BIDANG ENJINERING | T3: Rev | W3: : 00
D4: LAPORAN PDM TEKNOLOGI VIBRASI | T4: Hal | W4: : | AA4: INPUT NO | AC4: KET
A5: HASIL PENGUKURAN PADA EQUIPMENT BULAN JULI 2026
AA6: 7 | AC6: 1 | AD6: Januari
B7: NO | C7: EQUIPMENT | D7: CLASS / GROUP | E7: POSISI | W7: VIB MAX | X7: STATUS | AA7: 1 | AB7: 0.66 | AC7: 0.48 | AD7: 0.53 | AE7: 0.77 | AF7: 0.62 | AG7: 0.37 | AH7: 0.84 | AI7: 0.3 | AJ7: 0.37 | AK7: 0.82 | AL7: 0.42 | AM7: =MAX(AA7:AL7) -> 1 | AN7: =IF(AM7=0,"S/B",IF(AM7<2.4,"NORMAL",IF(AM7<4.6,"PREWARNING",IF(AM7<7.2,"WARNING","ALARM")))) -> NORMAL | AO7: 0.54 | AP7: 0.54 | AQ7: 0.69 | AR7: 0.72 | AS7: 1.15 | AT7: 0.95 | AU7: 0.42 | AV7: 0.66 | AW7: 0.5 | AX7: 0.66 | AY7: 0.74 | AZ7: 0.58 | BA7: =MAX(AO7:AZ7) -> 1.15 | BB7: =IF(BA7=0,"S/B",IF(BA7<2.4,"NORMAL",IF(BA7<4.6,"PREWARNING",IF(BA7<7.2,"WARNING","ALARM")))) -> NORMAL | BC7: 0.49 | BD7: 2.07 | BE7: 0.71 | BF7: 0.44 | BG7: 1.88 | BH7: 1.03 | BI7: 0.9 | BJ7: 2.41 | BK7: 1.34 | BL7: 2.16 | BM7: 3.27 | BN7: 1.22 | BO7: =MAX(BC7:BN7) -> 3.27 | BP7: =IF(BO7=0,"S/B",IF(BO7<2.4,"NORMAL",IF(BO7<4.6,"PREWARNING",IF(BO7<7.2,"WARNING","ALARM")))) -> PREWARNING | BQ7: 0.35 | BR7: 1.17 | BS7: 0.54 | BT7: 0.38 | BU7: 0.67 | BV7: 0.47 | BW7: 0.33 | BX7: 0.55 | BY7: 0.48 | BZ7: 0.48 | CA7: 0.72 | CB7: 0.47 | CC7: =MAX(BQ7:CB7) -> 1.17 | CD7: =IF(CC7=0,"S/B",IF(CC7<2.4,"NORMAL",IF(CC7<4.6,"PREWARNING",IF(CC7<7.2,"WARNING","ALARM")))) -> NORMAL | CE7: 1.73 | CF7: 2.18 | CG7: 2.55 | CH7: 1.59 | CI7: 2.5 | CJ7: 2.53 | CK7: 3.06 | CL7: 1.96 | CM7: 2.15 | CN7: 2.89 | CO7: 3.16 | CP7: 2.16 | CQ7: 2.78 | CR7: 2.34 | CS7: 2.75 | CT7: 3.37 | CU7: 3.4 | CV7: 2.82 | CW7: =MAX(CE7:CV7) -> 3.4 | CX7: =IF(CW7=0,"S/B",IF(CW7<2.4,"NORMAL",IF(CW7<4.6,"PREWARNING",IF(CW7<7.2,"WARNING","ALARM")))) -> PREWARNING | DQ7: =MAX(CY7:DP7) -> 0 | DR7: =IF(DQ7=0,"S/B",IF(DQ7<2.4,"NORMAL",IF(DQ7<4.6,"PREWARNING",IF(DQ7<7.2,"WARNING","ALARM")))) -> S/B | DV7: 2.01 | DW7: 2.25 | DX7: 2.47 | DY7: 1.4 | DZ7: 1.83 | EA7: 2.48 | EB7: 1.07 | EC7: 1.2 | ED7: 3.44 | EE7: =MAX(DS7:ED7) -> 3.44 | EF7: =IF(EE7=0,"S/B",IF(EE7<3.75,"NORMAL",IF(EE7<7.49,"PREWARNING",IF(EE7<9.9,"WARNING","ALARM")))) -> NORMAL | EG7: 2.04 | EH7: 3.11 | EI7: 0.99 | EJ7: 2.43 | EK7: 3.89 | EL7: 2.4 | EM7: 1.6 | EN7: 3.18 | EO7: 0.54 | EP7: 0.99 | EQ7: 3.05 | ER7: 1.33 | ES7: =MAX(EG7:ER7) -> 3.89 | ET7: =IF(ES7=0,"S/B",IF(ES7<1.5,"NORMAL",IF(ES7<2.9,"PREWARNING",IF(ES7<4.6,"WARNING","ALARM")))) -> WARNING | EU7: 0.84 | EV7: 1.95 | EW7: 0.35 | EX7: 1.7 | EY7: 2.14 | EZ7: 1.27 | FA7: 0.75 | FB7: 1.39 | FC7: 0.79 | FD7: 1.51 | FE7: 1.04 | FF7: 1.9 | FG7: =MAX(EU7:FF7) -> 2.14 | FH7: =IF(FG7=0,"S/B",IF(FG7<1.5,"NORMAL",IF(FG7<2.9,"PREWARNING",IF(FG7<4.6,"WARNING","ALARM")))) -> PREWARNING | FU7: =MAX(FI7:FT7) -> 0 | FV7: =IF(FU7=0,"S/B",IF(FU7<1.5,"NORMAL",IF(FU7<2.9,"PREWARNING",IF(FU7<4.6,"WARNING","ALARM")))) -> S/B | FW7: 0.62 | FX7: 1.35 | FY7: 0.35 | FZ7: 1.62 | GA7: 1.53 | GB7: 1.21 | GC7: 2.75 | GD7: 2.7 | GE7: 0.81 | GF7: 1.24 | GG7: 1.15 | GH7: 0.84 | GI7: =MAX(FW7:GH7) -> 2.75 | GJ7: =IF(GI7=0,"S/B",IF(GI7<1.5,"NORMAL",IF(GI7<2.9,"PREWARNING",IF(GI7<4.6,"WARNING","ALARM")))) -> PREWARNING | GW7: =MAX(GK7:GV7) -> 0 | GX7: =IF(GW7=0,"S/B",IF(GW7<1.5,"NORMAL",IF(GW7<2.9,"PREWARNING",IF(GW7<4.6,"WARNING","ALARM")))) -> S/B | GY7: 0.61 | GZ7: 1.18 | HA7: 0.94 | HB7: 1.02 | HC7: 1.84 | HD7: 1.32 | HE7: 5.03 | HF7: 5.45 | HG7: 3.71 | HH7: 1.73 | HI7: 1.8 | HJ7: 1.02 | HK7: =MAX(GY7:HJ7) -> 5.45 | HL7: =IF(HK7=0,"S/B",IF(HK7<2.4,"NORMAL",IF(HK7<4.5,"PREWARNING",IF(HK7<7.2,"WARNING","ALARM")))) -> WARNING | HY7: =MAX(HM7:HX7) -> 0 | HZ7: =IF(HY7=0,"S/B",IF(HY7<2.4,"NORMAL",IF(HY7<4.6,"PREWARNING",IF(HY7<7.2,"WARNING","ALARM")))) -> S/B | IA7: 0.71 | IB7: 0.68 | IC7: 0.42 | ID7: 0.9 | IE7: 0.93 | IF7: 0.81 | IG7: 1.23 | IH7: 0.79 | II7: 0.58 | IJ7: 0.79 | IK7: 0.79 | IL7: 0.93 | IM7: =MAX(IA7:IL7) -> 1.23 | IN7: =IF(IM7=0,"S/B",IF(IM7<1.4,"NORMAL",IF(IM7<2.8,"PREWARNING",IF(IM7<4.6,"WARNING","ALARM")))) -> NORMAL | IO7: 1.36 | IP7: 1.8 | IQ7: 0.64 | IR7: 1.86 | IS7: 2.15 | IT7: 1.4 | IU7: 1.58 | IV7: 1.05 | IW7: 0.86 | IX7: 1.07 | IY7: 0.86 | IZ7: 1.31 | JA7: =MAX(IO7:IZ7) -> 2.15 | JB7: =IF(JA7=0,"S/B",IF(JA7<1.5,"NORMAL",IF(JA7<2.9,"PREWARNING",IF(JA7<4.5,"WARNING","ALARM")))) -> PREWARNING
E8: 1V | F8: 1H | G8: 1A | H8: 2V | I8: 2H | J8: 2A | K8: 3V | L8: 3H | M8: 3A | N8: 4V | O8: 4H | P8: 4A | Q8: 5V | R8: 5H | S8: 5A | T8: 6V | U8: 6H | V8: 6A | AC8: 3 | AD8: Maret
C9: ='[1]INPUT EQUIPMENT'!A8 -> UNIT 1
B10: 1 | C10: ='[1]INPUT EQUIPMENT'!B9 -> Motor ID Fan 1#1 | D10: GROUP 1 | E10: 0.71 | F10: 0.77 | G10: 0.44 | H10: 1.36 | I10: 1.39 | J10: 0.77 | K10: 0.5 | L10: 0.64 | M10: 0.886 | N10: 0.55 | O10: 0.7 | P10: 0.53 | Q10: 0.49 | R10: 0.76 | S10: 0.61 | T10: 1.08 | U10: 2.21 | V10: 1.62 | W10: =MAX(E10:V10) -> 2.21 | X10: =IF(W10=0,"STAND BY",IF(W10<2.3,"NORMAL",IF(W10<4.6,"PREWARNING",IF(W10<7.2,"WARNING","ALARM")))) -> NORMAL | Z10: 2V | AA10: 0.99 | AB10: 5 | AC10: 0.39 | AD10: 1.34 | AE10: 4.47 | AF10: 1.37 | AG10: 0.74 | AH10: 4.27 | AI10: 1.26 | AJ10: 1.18 | AK10: 1.76 | AL10: 1.86 | AM10: =MAX(AA10:AL10) -> 5 | AN10: =IF(AM10=0,"S/B",IF(AM10<4.6,"NORMAL",IF(AM10<7.1,"PREWARNING",IF(AM10<8.01,"WARNING","ALARM")))) -> PREWARNING
B11: 2 | C11: ='[1]INPUT EQUIPMENT'!B10 -> Motor ID Fan 2#1 | D11: GROUP 1 | E11: 0.78 | F11: 1.18 | G11: 0.35 | H11: 0.82 | I11: 0.99 | J11: 0.39 | K11: 0.49 | L11: 0.93 | M11: 0.88 | N11: 0.3 | O11: 0.67 | P11: 0.54 | Q11: 0.72 | R11: 0.97 | S11: 0.74 | T11: 0.69 | U11: 2.25 | V11: 0.49 | W11: =MAX(E11:V11) -> 2.25 | X11: =IF(W11=0,"STAND BY",IF(W11<2.3,"NORMAL",IF(W11<4.6,"PREWARNING",IF(W11<7.2,"WARNING","ALARM")))) -> NORMAL | Z11: 3A | AA11: =29+19 -> 48
B12: 3 | C12: ='[1]INPUT EQUIPMENT'!B11 -> Motor Primary Air Fan 1#1 | D12: GROUP 1 | E12: 1.38 | F12: 2.82 | G12: 1.12 | H12: 1.62 | I12: 2.08 | J12: 1.14 | K12: 1.95 | L12: 2.51 | M12: 2.83 | N12: 3.13 | O12: 2.45 | P12: 3.07 | Q12: NA | R12: NA | S12: NA | T12: NA | U12: NA | V12: NA | W12: =MAX(E12:V12) -> 3.13 | X12: =IF(W12=0,"STAND BY",IF(W12<2.3,"NORMAL",IF(W12<4.6,"PREWARNING",IF(W12<7.2,"WARNING","ALARM")))) -> PREWARNING | Z12: 3H | AA12: =AA11*AA15 -> 0.576
B13: 4 | C13: ='[1]INPUT EQUIPMENT'!B12 -> Motor Primary Air Fan 2#1 | D13: GROUP 1 | E13: 1.06 | F13: 1.49 | G13: 1.65 | H13: 1.56 | I13: 1.77 | J13: 1.42 | K13: 2.32 | L13: 2.34 | M13: 2.74 | N13: 3.39 | O13: 3.38 | P13: 2.65 | Q13: NA | R13: NA | S13: NA | T13: NA | U13: NA | V13: NA | W13: =MAX(E13:V13) -> 3.39 | X13: =IF(W13=0,"STAND BY",IF(W13<2.3,"NORMAL",IF(W13<4.6,"PREWARNING",IF(W13<7.2,"WARNING","ALARM")))) -> PREWARNING | Z13: 4V
B14: 5 | C14: ='[1]INPUT EQUIPMENT'!B13 -> Motor Secondary Air Fan 1#1 | D14: GROUP 1 | E14: 0.92 | F14: 2.28 | G14: 0.58 | H14: 0.45 | I14: 1.67 | J14: 0.33 | K14: 0.68 | L14: 1.15 | M14: 0.55 | N14: 0.42 | O14: 0.9 | P14: 0.57 | Q14: NA | R14: NA | S14: NA | T14: NA | U14: NA | V14: NA | W14: =MAX(E14:V14) -> 2.28 | X14: =IF(W14=0,"STAND BY",IF(W14<2.3,"NORMAL",IF(W14<4.6,"PREWARNING",IF(W14<7.2,"WARNING","ALARM")))) -> NORMAL
B15: 6 | C15: ='[1]INPUT EQUIPMENT'!B14 -> Motor Secondary Air Fan 2#1 | D15: GROUP 1 | E15: 0.94 | F15: 2.33 | G15: 0.55 | H15: 0.78 | I15: 1.78 | J15: 0.4 | K15: 0.47 | L15: 1.31 | M15: 0.41 | N15: 0.49 | O15: 1.07 | P15: 0.41 | Q15: NA | R15: NA | S15: NA | T15: NA | U15: NA | V15: NA | W15: =MAX(E15:V15) -> 2.33 | X15: =IF(W15=0,"STAND BY",IF(W15<2.3,"NORMAL",IF(W15<4.6,"PREWARNING",IF(W15<7.2,"WARNING","ALARM")))) -> PREWARNING | AA15: 0.012
B16: 7 | C16: ='[1]INPUT EQUIPMENT'!B15 -> Turbin-Generator#1 | D16: GROUP 1 | E16: 2.71 | F16: 1.4 | G16: 0.86 | H16: 3.63 | I16: 1.5 | J16: 2.63 | K16: 3.59 | L16: 1.6 | M16: 2.34 | N16: 0.81 | O16: 0.77 | P16: 0.23 | Q16: NA | R16: NA | S16: NA | T16: NA | U16: NA | V16: NA | W16: =MAX(E16:V16) -> 3.63 | X16: =IF(W16=0,"STAND BY",IF(W16<3.8,"NORMAL",IF(W16<7.5,"PREWARNING",IF(W16<10.1,"WARNING","ALARM")))) -> NORMAL | Z16: 4H
B17: 8 | C17: ='[1]INPUT EQUIPMENT'!B16 -> Motor Condensat Pump 1#1 | D17: GROUP 2 | E17: 0 | F17: 0 | G17: 0 | H17: 0 | I17: 0 | J17: 0 | K17: 0 | L17: 0 | M17: 0 | N17: NA | O17: NA | P17: NA | Q17: NA | R17: NA | S17: NA | T17: NA | U17: NA | V17: NA | W17: =MAX(E17:V17) -> 0 | X17: =IF(W17=0,"STAND BY",IF(W17<1.5,"NORMAL",IF(W17<2.81,"PREWARNING",IF(W17<4.5,"WARNING","ALARM")))) -> STAND BY | Z17: 1V
B18: 9 | C18: ='[1]INPUT EQUIPMENT'!B17 -> Motor Condensat Pump 2#1 | D18: GROUP 2 | E18: 8.07 | F18: 7.31 | G18: 0 | H18: 2.29 | I18: 2.14 | J18: 1.15 | K18: 1.02 | L18: 1.14 | M18: 1.46 | N18: NA | O18: NA | P18: NA | Q18: NA | R18: NA | S18: NA | T18: NA | U18: NA | V18: NA | W18: =MAX(E18:V18) -> 8.07 | X18: =IF(W18=0,"STAND BY",IF(W18<1.4,"NORMAL",IF(W18<2.81,"PREWARNING",IF(W18<4.5,"WARNING","ALARM")))) -> ALARM | Z18: 1H | AA18: 3.4
B19: 10 | C19: ='[1]INPUT EQUIPMENT'!B18 -> Motor Vacuum Pump 1#1 | D19: GROUP 2 | E19: 0.54 | F19: 0.74 | G19: 0.43 | H19: 0.6 | I19: 0.8 | J19: 0.54 | K19: 0.9 | L19: 0.78 | M19: 0.52 | N19: 1.54 | O19: 1.06 | P19: 0.4 | Q19: NA | R19: NA | S19: NA | T19: NA | U19: NA | V19: NA | W19: =MAX(E19:V19) -> 1.54 | X19: =IF(W19=0,"STAND BY",IF(W19<1.4,"NORMAL",IF(W19<2.81,"PREWARNING",IF(W19<4.5,"WARNING","ALARM")))) -> PREWARNING | AA19: =AA18-AA12 -> 2.824
B20: 11 | C20: ='[1]INPUT EQUIPMENT'!B19 -> Motor Vacuum Pump 2#1 | D20: GROUP 2 | E20: 0.53 | F20: 0.73 | G20: 0.39 | H20: 0.62 | I20: 0.7 | J20: 0.46 | K20: 1.15 | L20: 0.97 | M20: 0.54 | N20: 1.26 | O20: 2.45 | P20: 0.37 | Q20: NA | R20: NA | S20: NA | T20: NA | U20: NA | V20: NA | W20: =MAX(E20:V20) -> 2.45 | X20: =IF(W20=0,"STAND BY",IF(W20<1.5,"NORMAL",IF(W20<2.81,"PREWARNING",IF(W20<4.5,"WARNING","ALARM")))) -> PREWARNING | Z20: 4A | AA20: 1.7
B21: 12 | C21: ='[1]INPUT EQUIPMENT'!B20 -> Motor Boiler Feed Pump 1#1 | D21: GROUP 2 | E21: 3.8 | F21: 2.06 | G21: 3.9 | H21: 4.2 | I21: 1.3 | J21: 2.63 | K21: 0.53 | L21: 2.77 | M21: 4.21 | N21: 0.76 | O21: 0.67 | P21: 1.08 | Q21: 1.81 | R21: 2.49 | S21: 1.26 | T21: 1.58 | U21: 1.84 | V21: 1.33 | W21: =MAX(E21:V21) -> 4.21 | X21: =IF(W21=0,"STAND BY",IF(W21<2.4,"NORMAL",IF(W21<4.6,"PREWARNING",IF(W21<7.2,"WARNING","ALARM")))) -> PREWARNING | AA21: =AA19-AA20 -> 1.124
B22: 13 | C22: ='[1]INPUT EQUIPMENT'!B21 -> Motor Boiler Feed Pump 2#1 | D22: GROUP 2 | E22: 1.02 | F22: 1.07 | G22: 1.62 | H22: 1.1 | I22: 0.94 | J22: 0.85 | K22: 0.61 | L22: 2.15 | M22: 0.9 | N22: 0.45 | O22: 1.12 | P22: 1.22 | Q22: 3.52 | R22: 4.16 | S22: 0.34 | T22: 1.46 | U22: 1.84 | V22: 0.58 | W22: =MAX(E22:V22) -> 4.16 | X22: =IF(W22=0,"STAND BY",IF(W22<2.4,"NORMAL",IF(W22<4.6,"PREWARNING",IF(W22<7.2,"WARNING","ALARM")))) -> PREWARNING | Z22: 4H | AA22: =AA21/AA15 -> 93.666667
B23: 14 | C23: ='[1]INPUT EQUIPMENT'!B22 -> Motor CCCWP 1#1 | D23: GROUP 2 | E23: 1.87 | F23: 1.88 | G23: NA | H23: 1.72 | I23: 1.13 | J23: 0.61 | K23: 1.1 | L23: 0.71 | M23: 0.7 | N23: NA | O23: NA | P23: NA | Q23: NA | R23: NA | S23: NA | T23: NA | U23: NA | V23: NA | W23: =MAX(E23:V23) -> 1.88 | X23: =IF(W23=0,"STAND BY",IF(W23<1.5,"NORMAL",IF(W23<2.81,"PREWARNING",IF(W23<4.5,"WARNING","ALARM")))) -> PREWARNING | Z23: 1H
B24: 15 | C24: ='[1]INPUT EQUIPMENT'!B23 -> Motor CCCWP 2#1 | D24: GROUP 2 | E24: 2.13 | F24: 1.39 | G24: NA | H24: 1.12 | I24: 0.69 | J24: 0.58 | K24: 0.58 | L24: 0.4 | M24: 0.35 | N24: NA | O24: NA | P24: NA | Q24: NA | R24: NA | S24: NA | T24: NA | U24: NA | V24: NA | W24: =MAX(E24:V24) -> 2.13 | X24: =IF(W24=0,"STAND BY",IF(W24<1.5,"NORMAL",IF(W24<2.81,"PREWARNING",IF(W24<4.5,"WARNING","ALARM")))) -> PREWARNING | Z24: 1V
B25: 16 | C25: ='[1]INPUT EQUIPMENT'!B24 -> Motor CWP 355 Kw 1#1 | D25: GROUP 2 | E25: 1.87 | F25: 2.34 | G25: 1.4 | H25: 0.59 | I25: 0.53 | J25: 0.34 | K25: 0.37 | L25: 0.43 | M25: 0.45 | N25: NA | O25: NA | P25: NA | Q25: NA | R25: NA | S25: NA | T25: NA | U25: NA | V25: NA | W25: =MAX(E25:V25) -> 2.34 | X25: =IF(W25=0,"STAND BY",IF(W25<2.4,"NORMAL",IF(W25<4.6,"PREWARNING",IF(W25<7.2,"WARNING","ALARM")))) -> NORMAL | Z25: 1A
B26: 17 | C26: ='[1]INPUT EQUIPMENT'!B25 -> Motor CWP 355 Kw 2#1 | D26: GROUP 2 | E26: 1.11 | F26: 0.67 | G26: 0.97 | H26: 0.45 | I26: 0.86 | J26: 0.4 | K26: 0.26 | L26: 0.25 | M26: 0.35 | N26: NA | O26: NA | P26: NA | Q26: NA | R26: NA | S26: NA | T26: NA | U26: NA | V26: NA | W26: =MAX(E26:V26) -> 1.11 | X26: =IF(W26=0,"STAND BY",IF(W26<2.4,"NORMAL",IF(W26<4.6,"PREWARNING",IF(W26<7.2,"WARNING","ALARM")))) -> NORMAL | Z26: 1A
B27: 18 | C27: ='[1]INPUT EQUIPMENT'!B26 -> Motor BWRO 1#1 | D27: GROUP 2 | E27: 0.96 | F27: 1.01 | G27: 0 | H27: 1.03 | I27: 1.06 | J27: 0.79 | K27: NA | L27: NA | M27: NA | N27: NA | O27: NA | P27: NA | Q27: NA | R27: NA | S27: NA | T27: NA | U27: NA | V27: NA | W27: =MAX(E27:V27) -> 1.06 | X27: =IF(W27=0,"STAND BY",IF(W27<1.5,"NORMAL",IF(W27<2.81,"PREWARNING",IF(W27<4.5,"WARNING","ALARM")))) -> NORMAL | Z27: 1V
B28: 19 | C28: ='[1]INPUT EQUIPMENT'!B27 -> Motor BWRO 2#1 | D28: GROUP 2 | E28: 1.52 | F28: 1.64 | G28: 0 | H28: 1.05 | I28: 0.68 | J28: 0.8 | K28: NA | L28: NA | M28: NA | N28: NA | O28: NA | P28: NA | Q28: NA | R28: NA | S28: NA | T28: NA | U28: NA | V28: NA | W28: =MAX(E28:V28) -> 1.64 | X28: =IF(W28=0,"STAND BY",IF(W28<1.5,"NORMAL",IF(W28<2.81,"PREWARNING",IF(W28<4.5,"WARNING","ALARM")))) -> PREWARNING
B29: 20 | C29: ='[1]INPUT EQUIPMENT'!B28 -> Motor SWRO 1 #1 | D29: GROUP 2 | E29: 0 | F29: 0 | G29: 0 | H29: 0 | I29: 0 | J29: 0 | K29: NA | L29: NA | M29: NA | N29: NA | O29: NA | P29: NA | Q29: NA | R29: NA | S29: NA | T29: NA | U29: NA | V29: NA | W29: =MAX(E29:V29) -> 0 | X29: =IF(W29=0,"STAND BY",IF(W29<1.5,"NORMAL",IF(W29<2.81,"PREWARNING",IF(W29<4.5,"WARNING","ALARM")))) -> STAND BY | Z29: 1H
B30: 21 | C30: ='[1]INPUT EQUIPMENT'!B29 -> Motor SWRO 2#1 | D30: GROUP 2 | E30: 0.43 | F30: 1.02 | G30: 0.08 | H30: 0.27 | I30: 1.24 | J30: 0.28 | K30: NA | L30: NA | M30: NA | N30: NA | O30: NA | P30: NA | Q30: NA | R30: NA | S30: NA | T30: NA | U30: NA | V30: NA | W30: =MAX(E30:V30) -> 1.24 | X30: =IF(W30=0,"STAND BY",IF(W30<1.5,"NORMAL",IF(W30<2.81,"PREWARNING",IF(W30<4.5,"WARNING","ALARM")))) -> NORMAL | Z30: 1H
B31: 22 | C31: AC OIL PUMP UNIT 1 | D31: GROUP 2 | E31: 0.35 | F31: 1.06 | G31: 0.26 | H31: 0.3 | I31: 0.67 | J31: 0.71 | K31: 0.62 | L31: 0.85 | M31: 0.21 | N31: 0.4 | O31: 0.5 | P31: 0.23 | Q31: NA | R31: NA | S31: NA | T31: NA | U31: NA | V31: NA | W31: =MAX(E31:V31) -> 1.06 | X31: =IF(W31=0,"STAND BY",IF(W31<1.4,"NORMAL",IF(W31<2.81,"PREWARNING",IF(W31<4.5,"WARNING","ALARM")))) -> NORMAL | Z31: 1H
B32: 23 | C32: DC OIL PUMP UNIT 1 | D32: GROUP 2 | E32: 1.17 | F32: 0.87 | G32: 0.92 | H32: 0.99 | I32: 1.46 | J32: 1.21 | K32: 1.34 | L32: 1.95 | M32: 0.76 | N32: 1.07 | O32: 1.28 | P32: 0.74 | Q32: NA | R32: NA | S32: NA | T32: NA | U32: NA | V32: NA | W32: =MAX(E32:V32) -> 1.95 | X32: =IF(W32=0,"STAND BY",IF(W32<1.4,"NORMAL",IF(W32<2.81,"PREWARNING",IF(W32<4.5,"WARNING","ALARM")))) -> PREWARNING | Z32: 1H
B33: 24 | C33: DIESEL FIRE FIGHTING UNIT 1 | E33: 7.65 | F33: 6.11 | G33: 6.23 | H33: 12.07 | I33: 9.52 | J33: 7.39 | K33: 3.36 | L33: 3.2 | M33: 3.56 | N33: 3.12 | O33: 3.33 | P33: 3.41 | Q33: NA | R33: NA | S33: NA | T33: NA | U33: NA | V33: NA | W33: =MAX(E33:V33) -> 12.07 | X33: =IF(W33=0,"STAND BY",IF(W33<4.46,"NORMAL",IF(W33<28.2,"PREWARNING",IF(W33<44.6,"WARNING","ALARM")))) -> PREWARNING | Z33: 1H
B34: 25 | C34: ELECTRIC FIRE FIGHTING UNIT 1 | D34: GROUP 2 | E34: 1.6 | F34: 1.28 | G34: 1.72 | H34: 1.81 | I34: 1.44 | J34: 1.88 | K34: 2.13 | L34: 2.04 | M34: 2.36 | N34: 2.15 | O34: 2.63 | P34: 2.12 | Q34: NA | R34: NA | S34: NA | T34: NA | U34: NA | V34: NA | W34: =MAX(E34:V34) -> 2.63 | X34: =IF(W34=0,"STAND BY",IF(W34<1.4,"NORMAL",IF(W34<2.81,"PREWARNING",IF(W34<4.5,"WARNING","ALARM")))) -> PREWARNING | Z34: 1H
B35: 26 | C35: JOCKEY FIGHTING UNIT 1 | D35: GROUP 2 | E35: 0.86 | F35: 0.87 | G35: N/A | H35: 0.72 | I35: 0.78 | J35: 0.21 | K35: NA | L35: NA | M35: NA | N35: NA | O35: NA | P35: NA | Q35: NA | R35: NA | S35: NA | T35: NA | U35: NA | V35: NA | W35: =MAX(E35:V35) -> 0.87 | X35: =IF(W35=0,"STAND BY",IF(W35<1.4,"NORMAL",IF(W35<2.81,"PREWARNING",IF(W35<4.5,"WARNING","ALARM")))) -> NORMAL | Z35: 1H
C36: ='[1]INPUT EQUIPMENT'!A30 -> UNIT 2
B37: 1 | C37: ='[1]INPUT EQUIPMENT'!B31 -> Motor ID Fan 1#2 | D37: GROUP 1 | E37: 0.76 | F37: 1.81 | G37: 0.47 | H37: 0.66 | I37: 1.59 | J37: 0.46 | K37: 0.76 | L37: 1.26 | M37: 0.8 | N37: 0.4 | O37: 1.29 | P37: 0.41 | Q37: 0.7 | R37: 1.15 | S37: 0.54 | T37: 0.51 | U37: 1.05 | V37: 0.49 | W37: =MAX(E37:V37) -> 1.81 | X37: =IF(W37=0,"STAND BY",IF(W37<2.3,"NORMAL",IF(W37<4.6,"PREWARNING",IF(W37<7.2,"WARNING","ALARM")))) -> NORMAL | Z37: 2V
B38: 2 | C38: ='[1]INPUT EQUIPMENT'!B32 -> Motor ID Fan 2#2 | D38: GROUP 1 | E38: 0.51 | F38: 0.97 | G38: 0.69 | H38: 1.15 | I38: 0.97 | J38: 0.61 | K38: 0.7 | L38: 1.03 | M38: 1.62 | N38: 0.51 | O38: 0.69 | P38: 0.81 | Q38: 0.81 | R38: 1.11 | S38: 0.54 | T38: 0.66 | U38: 0.81 | V38: 0.58 | W38: =MAX(E38:V38) -> 1.62 | X38: =IF(W38=0,"STAND BY",IF(W38<2.3,"NORMAL",IF(W38<4.6,"PREWARNING",IF(W38<7.2,"WARNING","ALARM")))) -> NORMAL | Z38: 3A | AA38: =29+19 -> 48
B39: 3 | C39: ='[1]INPUT EQUIPMENT'!B33 -> Motor Primary Air Fan 1#2 | D39: GROUP 1 | E39: 0.44 | F39: 1.54 | G39: 0.97 | H39: 0.86 | I39: 1.36 | J39: 0.6 | K39: 0.98 | L39: 1.78 | M39: 1.11 | N39: 1.82 | O39: 2.23 | P39: 1.16 | Q39: NA | R39: NA | S39: NA | T39: NA | U39: NA | V39: NA | W39: =MAX(E39:V39) -> 2.23 | X39: =IF(W39=0,"STAND BY",IF(W39<2.3,"NORMAL",IF(W39<4.6,"PREWARNING",IF(W39<7.2,"WARNING","ALARM")))) -> NORMAL | Z39: 3H | AA39: =AA38*AA42 -> 0.576
B40: 4 | C40: ='[1]INPUT EQUIPMENT'!B34 -> Motor Primary Air Fan 2#2 | D40: GROUP 1 | E40: 1.22 | F40: 2.43 | G40: 1.04 | H40: 2.84 | I40: 2.41 | J40: 1.2 | K40: 0.86 | L40: 2.13 | M40: 0.7 | N40: 1.27 | O40: 1.35 | P40: 0.63 | Q40: NA | R40: NA | S40: NA | T40: NA | U40: NA | V40: NA | W40: =MAX(E40:V40) -> 2.84 | X40: =IF(W40=0,"STAND BY",IF(W40<2.3,"NORMAL",IF(W40<4.6,"PREWARNING",IF(W40<7.2,"WARNING","ALARM")))) -> PREWARNING | Z40: 4V
...

Sheet REKOMENDASI
E1: PT. PLN INDONESIA POWER | K1: No. Dok : FORM.JRG.F.05.001
E2: UNIT BISNIS PEMBANGKITAN JERANJANG | K2: Tgl Terbit : 1 Sep 2016
E3: BIDANG ENJINERING | K3: Rev : 00
E4: LAPORAN PDM TEKNOLOGI VIBRASI | K4: Hal :
A5: HASIL PENGUKURAN PADA EQUIPMENT BULAN JULI 2018 | B5: EXECUTIVE SUMMARY
C7: NO | D7: EQUIPMENT | E7: PENGUKURAN BULAN SEBELUMNYA | G7: PENGUKURAN BULAN MEI | I7: STATUS | J7: ANALISA | K7: REKOMENDASI | N7: Week | O7: Tanggal | P7: Analisa | Q7: Rekomendasi | R7: ACTION HAR | S7: KETERANGAN
E8: POSISI | F8: VIB MAX | G8: POSISI | H8: VIB MAX
D9: ='[1]INPUT EQUIPMENT'!A8 -> UNIT 1
A10: 43 | C10: 1 | D10: ='[1]INPUT EQUIPMENT'!B9 -> Motor ID Fan 1#1 | E10: 2H | F10: 2.23 | G10: 2H | H10: 2.21 | I10: NORMAL | J10: Secara overall nilai vibrasi IDF 1A masuk level NORMAL (level A) dengan keterangan kondisi sangat halus (new machine condition), berdasarkan ISO 10816-3 group 1 rigid. Nilai vibrasi overall tertinggi 2,21 mm/s pada bearing 6 arah horisontal | K10: - Lakukan monitoring vibrasi secara rutin dan berkala | N10: W1
A11: 44 | C11: 2 | D11: ='[1]INPUT EQUIPMENT'!B10 -> Motor ID Fan 2#1 | E11: 6H | F11: 2.09 | G11: 6H | H11: 2.25 | I11: NORMAL | J11: Secara overall nilai vibrasi IDF 1B masuk level NORMAL (level A) dengan keterangan kondisi sangat halus (new machine condition), berdasarkan ISO 10816-3 group 1 rigid. Nilai vibrasi overall tertinggi 2,25 mm/s pada bearing 6 arah horisontal | K11: - Lakukan monitoring vibrasi secara rutin dan berkala | N11: W3
A12: 45 | C12: 3 | D12: ='[1]INPUT EQUIPMENT'!B11 -> Motor Primary Air Fan 1#1 | E12: 4V | F12: 3.43 | G12: 4V | H12: 3.13 | I12: PREWARNING | J12: Secara overall nilai vibrasi PAF 1A masuk level PREWARNING (level B) dengan keterangan diperbolehkan beroperasi dalam jangka waktu lama, berdasarkan ISO 10816-3 group 1 rigid. Nilai vibrasi overall tertinggi 3,13 mm/s pada bearing 4 arah vertikal | K12: - Lakukan monitoring vibrasi secara rutin dan berkala | N12: W1
A13: 46 | C13: 4 | D13: ='[1]INPUT EQUIPMENT'!B12 -> Motor Primary Air Fan 2#1 | E13: 2H | F13: 1.65 | G13: 2H | H13: 3.39 | I13: PREWARNING | J13: Secara overall nilai vibrasi PAF 1B masuk level PREWARNING (level B) dengan keterangan diperbolehkan beroperasi dalam jangka waktu lama, berdasarkan berdasarkan ISO 10816-3 group 1 rigid. Nilai vibrasi overall tertinggi 3,39 mm/s pada bearing 4 arah vertikal | K13: - Lakukan monitoring vibrasi secara rutin dan berkala | N13: W3
A14: 47 | C14: 5 | D14: ='[1]INPUT EQUIPMENT'!B13 -> Motor Secondary Air Fan 1#1 | E14: 1H | F14: 2.05 | G14: 1H | H14: 2.28 | I14: NORMAL | J14: Secara overall nilai vibrasi SAF 1A masuk level NORMAL (level A) dengan keterangan kondisi sangat halus (new machine condition), berdasarkan ISO 10816-3 group 1 rigid. Nilai vibrasi overall tertinggi 2,29 mm/s pada bearing 1 arah horisontal | K14: - Lakukan monitoring vibrasi secara rutin dan berkala | N14: W1
A15: 48 | C15: 6 | D15: ='[1]INPUT EQUIPMENT'!B14 -> Motor Secondary Air Fan 2#1 | E15: 1H | F15: 3.7 | G15: 1H | H15: 2.33 | I15: PREWARNING | J15: Secara overall nilai vibrasi SAF 1B masuk level PREWARNING (level B) dengan keterangan diperbolehkan beroperasi dalam jangka waktu lama, berdasarkan ISO 10816-3 group 1 rigid. Nilai vibrasi overall tertinggi 2,33 mm/s pada bearing 1 arah horisontal after perbaikan blade | K15: Lakukan Penjadwalan atau perencaan Perbaikan saat Unit Stop | N15: W3
A16: 49 | C16: 7 | D16: ='[1]INPUT EQUIPMENT'!B15 -> Turbin-Generator#1 | E16: 2V | F16: 3.28 | G16: 2V | H16: 3.63 | I16: NORMAL | J16: Secara overaal nilai vibrasi turbine dan generator unit 1 masuk level NORMAL (level A) dengan keterangan kondisi sangat halus (new machine condition), berdasarkan standart ISO 10816-2 Nilai vibrasi overall tertinggi 3,63 mm/s pada bearing 2 arah vertikal | K16: - Monitoring parameter operasi (vibrasi dan temperatur) | N16: W1
A17: 50 | C17: 8 | D17: ='[1]INPUT EQUIPMENT'!B16 -> Motor Condensat Pump 1#1 | E17: 1H | F17: 1.08 | G17: 1H | H17: 0 | I17: STAND BY | J17: - | K17: - | N17: W2
A18: 51 | C18: 9 | D18: ='[1]INPUT EQUIPMENT'!B17 -> Motor Condensat Pump 2#1 | E18: 1V | F18: 4.41 | G18: 1V | H18: 8.07 | I18: ALARM | J18: Secara overall nilai vibrasi CEP 1B masuk level ALARM (level D) dengan keterangan jika dioperasikan akan mengakibatkan kerusakan yang lebih parah, berdasarkan berdasarkan ISO 10816-3 group 2 rigid. Nilai vibrasi overall tertinggi 8,07 mm/s pada bearing 1 arah vertikal dari hasil pengukuran specturm muncul indikasi bent shaft dan cocked sudah di terbitkan TE dengan No 09.TE/CBM/UBPJRJ/2026 dan SR CD No JRJ26/2026151037 | K18: - Lakukan monitoring vibrasi secara rutin dan berkala - Solo run (before&after pekerjaan) - Pengecekan kondisi pelumasan beairng - Pengecekan kondisi bearing, lakukan penggantian jika ditemukan kerusakan - Pengecekan kondisi Housing bearing motor - Pengecekan kondisi shaft, lakukan run out check - Re-alignment motor dan pompa - Pemasangan baut dudukan motor dan pompa pastikan menggunakan ring, - pengencangan baut dengan rata - Post Test Maintenance | N18: W4
A19: 52 | C19: 10 | D19: ='[1]INPUT EQUIPMENT'!B18 -> Motor Vacuum Pump 1#1 | E19: 4V | F19: 1.46 | G19: 4V | H19: 1.54 | I19: PREWARNING | J19: Secara overall nilai vibrasi vacuum pump 1A masuk level PREWARNING (level B) dengan keterangan diperbolehkan beroperasi dalam jangka waktu lama, berdasarkan ISO 10816-3 group 2 rigid. Nilai vibrasi overall tertinggi 1,54 mm/s pada bearing 4 arah vertikal | K19: - monitoring parameter operasi | N19: W3
A20: 53 | C20: 11 | D20: ='[1]INPUT EQUIPMENT'!B19 -> Motor Vacuum Pump 2#1 | E20: 4H | F20: 1.91 | G20: 4H | H20: 2.45 | I20: PREWARNING | J20: Secara overall nilai vibrasi vacuum pump 1B masuk level PREWARNING (level B) dengan keterangan diperbolehkan beroperasi dalam jangka waktu lama, berdasarkan ISO 10816-3 group 2 rigid. Nilai vibrasi overall tertinggi 2,45 mm/s pada bearing 4 arah horisontal | K20: - monitoring parameter operasi - inject grease 5x pada bearing 3 | N20: W3
A21: 54 | C21: 12 | D21: ='[1]INPUT EQUIPMENT'!B20 -> Motor Boiler Feed Pump 1#1 | E21: 2A | F21: 3.05 | G21: 2A | H21: 4.21 | I21: PREWARNING | J21: Secara overall nilai vibrasi BFP 1A masuk level PREWARNING (level B) dengan keterangan diperbolehkan beroperasi dalam jangka waktu lama, berdasarkan ISO 10816-3 group 1 rigid. Nilai vibrasi overall tertinggi 4,20 mm/s pada bearing 2 arah vertikal | K21: - monitoring parameter operasi | N21: W4
... A28: 61 | C28: 19 | D28: ='[1]INPUT EQUIPMENT'!B27 -> Motor BWRO 2#1 | E28: 1H | F28: 2.05 | G28: 1H | H28: 1.64 | I28: PREWARNING | J28: Secara overall nilai vibrasi BWRO 1B masuk level PREWARNING (level B) dengan keterangan diperbolehkan beroperasi dalam jangka waktu lama, berdasarkan ISO 10816-3 group 2 rigid. Nilai vibrasi overall tertinggi 1,64 mm/s pada bearing 1 arah horisontal | K28: - monitoring parameter operasi | N28: W3
A29: 62 | C29: 20 | D29: ='[1]INPUT EQUIPMENT'!B28 -> Motor SWRO 1 #1 | E29: 2H | F29: 1.19 | G29: 2H | H29: 0 | I29: STAND BY | J29: - | K29: - | N29: W1 | Q29: LJ30-PDM-VIB-0026-1V
A30: 63 | C30: 21 | D30: ='[1]INPUT EQUIPMENT'!B29 -> Motor SWRO 2#1 | E30: 1H | F30: 1.21 | G30: 1H | H30: 1.24 | I30: NORMAL | J30: Secara overall nilai vibrasi SWRO 1B masuk level NORMAL (level A) dengan keterangan kondisi sangat halus (new machine condition), berdasarkan ISO 10816-3 group 2 rigid. Nilai vibrasi overall tertinggi 1,24 pada bearing 2 arah horisontal | K30: - monitoring parameter operasi | N30: W3
A31: 63 | C31: 23 | D31: AC OIL PUMP UNIT 1 | E31: 1H | F31: 1.26 | G31: 1H | H31: 1.06 | I31: NORMAL | J31: Secara overall nilai vibrasi AC Oil Pump Unit 1 masuk level NORMAL (level A) dengan keterangan kondisi sangat halus (new machine condition), berdasarkan ISO 10816-3 group 2 rigid. Nilai vibrasi overall tertinggi 1,06 mm/s pada bearing 1 arah horisontal | K31: - monitoring parameter operasi | N31: W2
A32: 63 | C32: 24 | D32: DC OIPL PUMP UNIT 1 | E32: 3H | F32: 1.58 | G32: 3H | H32: 1.95 | I32: PREWARNING | J32: Secara overall nilai vibrasi DC Oil Pump Unit 1 level REWARNING (level B) dengan keterangan diperbolehkan beroperasi dalam jangka waktu lama, berdasarkan ISO 10816-3 group 2 rigid. Nilai vibrasi overall tertinggi 1,54 mm/s pada bearing 3 arah horisontal | K32: - monitoring parameter operasi | N32: W2
A33: 63 | C33: 25 | D33: DIESEL FIRE FIGHTING UNIT 1 | E33: 2V | F33: 13.55 | G33: 2V | H33: 12.07 | I33: PREWARNING | J33: Secara overaal nilai vibrasi DIESEL FIRE FIGHTING UNIT 1 masuk level PREWARNING (level B) dengan keterangan boleh dioperasikan dalam jangka waktu lama, berdasarkan standart ISO 10816-3 group 2 rigid. Nilai vibrasi overall tertinggi 12,1 mm/s pada bearing 2 arah vertikal | K33: - Pemantauan parameter operasi current dan temperatur | N33: W2
A34: 63 | C34: 26 | D34: ELECTRIC FIRE FIGHTING UNIT 1 | E34: 2V | F34: 2.62 | G34: 2V | H34: 2.63 | I34: PREWARNING | J34: Secara overaal nilai vibrasi FIRE FIGHTING PUMP WITH MOTOR Unit 1 masuk level PREWARNING (level B) dengan keterangan diperbolehkan beroperasi dalam jangka waktu lama, berdasarkan standart ISO 10816-3 group 2 rigid. Nilai vibrasi overall tertinggi 2,63 mm/s pada bearing 4 arah vertikal | K34: - Pemantauan parameter operasi current dan temperatur | N34: W2
A35: 63 | C35: 27 | D35: JOCKEY FIGHTING UNIT 1 | E35: 1V | F35: 1.07 | G35: 1V | H35: 0.87 | I35: NORMAL | J35: Secara overaal nilai vibrasi JACKING OIL PUMP 1A masuk level NORMAL (level A) dengan keterangan kondisi sangat halus (new machine condition), berdasarkan standart ISO 10816-3 group 2 rigid. Nilai vibrasi overall tertinggi 0,87 mm/s pada bearing 1 arah horisontal | K35: - Pemantauan parameter operasi current dan temperatur | N35: W2
D36: ='[1]INPUT EQUIPMENT'!A30 -> UNIT 2
A37: 43 | C37: 25 | D37: ='[1]INPUT EQUIPMENT'!B31 -> Motor ID Fan 1#2 | E37: 1H | F37: 1.9 | G37: 1H | H37: 1.81 | I37: NORMAL | J37: Secara overall nilai vibrasi IDF 1 unit 2 masuk level NORMAL (level A) dengan keterangan kondisi sangat halus (new machine condition), ISO 10816-3 group 1 rigid. Nilai vibrasi overall tertinggi 1,81 mm/s pada bearing 1 arah horisontal | K37: - Lakukan monitoring vibrasi secara rutin dan berkala | N37: W3
A38: 44 | C38: 26 | D38: ='[1]INPUT EQUIPMENT'!B32 -> Motor ID Fan 2#2 | E38: 3A | F38: 2.3 | G38: 3A | H38: 1.62 | I38: NORMAL | J38: Secara overall nilai vibrasi IDF 2 unit 2 masuk leve NORMAL (level A) dengan keterangan kondisi sangat halus (new machine condition), ISO 10816-3 group 1 rigid. Nilai vibrasi overall tertinggi 1,62 mm/s pada bearing 3 arah axial | K38: - Lakukan monitoring vibrasi secara rutin dan berkala | N38: W1
A39: 45 | C39: 27 | D39: ='[1]INPUT EQUIPMENT'!B33 -> Motor Primary Air Fan 1#2 | E39: 4H | F39: 2.48 | G39: 4H | H39: 2.23 | I39: NORMAL | J39: Secara overall nilai vibrasi PAF 1 unit 2 masuk level NORMAL (level A) dengan keterangan kondisi sangat halus (new machine condition), berdasarkan ISO 10816-3 group 1 rigid. Nilai vibrasi overall tertinggi 2,23 mm/s pada bearing 4 arah horisontal | K39: - Monitoring parameter operasi, arus, bukaan damper, flow | N39: W3 | P39: LJ30LAY10AA010-001
A40: 46 | C40: 28 | D40: ='[1]INPUT EQUIPMENT'!B34 -> Motor Primary Air Fan 2#2 | E40: 1H | F40: 2.8 | G40: 1H | H40: 2.84 | I40: PREWARNING | J40: Secara overall nilai vibrasi PAF 2 unit 2 masuk level PREWARNING (level B) dan diperbolehkan beroperasi dalam jangka waktu lama yang tak terbatas, berdasarkan berdasarkan ISO 10816-3 group 1 rigid. Nilai vibrasi overall tertinggi 2,84 mm/s pada bearing 2 arah horisontal | K40: - Lakukan monitoring vibrasi secara rutin dan berkala | N40: W1
A41: 47 | C41: 29 | D41: ='[1]INPUT EQUIPMENT'!B35 -> Motor Secondary Air Fan 1#2 | E41: 3H | F41: 2.94 | G41: 3H | H41: 2.9 | I41: PREWARNING | J41: Secara overall nilai vibrasi SAF 1 masuk level PREWARNING (level B) dan diperbolehkan beroperasi dalam jangka waktu lama yang tak terbatas, berdasarkan ISO 10816-3 group 1 rigid. Nilai vibrasi overall tertinggi 2,90 mm/s pada bearing 3 arah horisontal | K41: - Lakukan monitoring vibrasi secara rutin dan berkala | N41: W3
A42: 48 | C42: 30 | D42: ='[1]INPUT EQUIPMENT'!B36 -> Motor Secondary Air Fan 2#2 | E42: 1H | F42: 2.45 | G42: 1H | H42: 2.72 | I42: PREWARNING | J42: Secara overall nilai vibrasi SAF 2 masuk level PREWARNING (level B) dan diperbolehkan beroperasi dalam jangka waktu lama yang tak terbatas, berdasarkan ISO 10816-3 group 1 rigid. Nilai vibrasi overall tertinggi 2,72 mm/s pada bearing 1 arah horisontal | K42: - Lakukan monitoring vibrasi secara rutin dan berkala | N42: W1
A43: 49 | C43: 31 | D43: ='[1]INPUT EQUIPMENT'!B37 -> Turbin-Generator#2 | E43: 4A | F43: 4.6 | G43: 4A | H43: 5.85 | I43: PREWARNING | J43: Secara overaal nilai vibrasi turbine dan generator unit 2 masuk level PREWARNING (level B) dan diperbolehkan beroperasi dalam jangka waktu lama yang tak terbatas, berdasarkan standart ISO 10816-2 Nilai vibrasi overall tertinggi 5,85 mm/s pada bearing 4 arah axial | K43: - Monitoring parameter operasi (vibrasi dan temperatur) | N43: W3
A44: 50 | C44: 32 | D44: ='[1]INPUT EQUIPMENT'!B38 -> Motor Condensat Pump 1#2 | E44: 2H | F44: 0.83 | G44: 2H | H44: 0 | I44: STAND BY | J44: - | K44: - | N44: W4
A45: 51 | C45: 33 | D45: ='[1]INPUT EQUIPMENT'!B39 -> Motor Condensat Pump 2#2 | E45: 1V | F45: 4.41 | G45: 1V | H45: 1.2 | I45: NORMAL | J45: Secara overall nilai vibrasi CEP 2 masuk level NORMAL (level A) dengan keterangan kondisi sangat halus (new machine condition), berdasarkan ISO 10816-3 group 2 rigid. Nilai vibrasi overall tertinggi 1,20 mm/s pada bearing 1 arah horisontal | K45: - Lakukan monitoring vibrasi secara rutin dan berkala | N45: W2
A46: 52 | C46: 34 | D46: ='[1]INPUT EQUIPMENT'!B40 -> Motor Vacuum Pump 1#2 | E46: 4H | F46: 1.72 | G46: 4H | H46: 1.5 | I46: PREWARNING | J46: Secara overall nilai vibrasi vacuum pump 1 masuk level PREWARNING (level B) dan diperbolehkan beroperasi dalam jangka waktu lama yang tak terbatas, berdasarkan ISO 10816-3 group 2 rigid. Nilai vibrasi overall tertinggi 1,72 mm/s pada bearing 4 arah horisontal | K46: - monitoring parameter operasi - inject grease 5x pada bearing 3 dan 4 | N46: W3
A47: 53 | C47: 35 | D47: ='[1]INPUT EQUIPMENT'!B41 -> Motor Vacuum Pump 2#2 | E47: 4H | F47: 2.7 | G47: 4H | H47: 1.5 | I47: PREWARNING | J47: Secara overall nilai vibrasi vacuum pump 2 masuk level PREWARNING (level B) dan diperbolehkan beroperasi dalam jangka waktu lama yang tak terbatas, berdasarkan ISO 10816-3 group 2 rigid. Nilai vibrasi overall tertinggi 2,70 mm/s pada bearing 4 arah horisontal | K47: - monitoring parameter operasi - inject grease 5x pada bearing 3 dan 4 | N47: W3
...
